Workbook

Sheet Kalkulator
B1: Kalkulator diety zagranicznej | D1: Kontrola danych: | E1: {=IF(C15="","Wybierz kraj w etapie 1",IF(SUMPRODUCT((C16:C19<>"")*(C15:C18=""))>0,"Nie zostawiaj pustego etapu między krajami",IF(SUMPRODUCT(--ISTEXT(D15:D20))+SUMPRODUCT(--ISTEXT(I15:J19))+ISTEXT(K5)+ISTEXT(K6)+ISTEXT(K7)+ISTEXT(C9)>0,"Niepoprawna data (wpisz np. 14.09.2026 10:30) – zobacz czerwone pole",IF(SUMPRODUCT((C15:C19<>"")*(D15:D19=""))>0,"Uzupełnij datę wjazdu w każdym etapie",IF(SUMPRODUCT((C16:C19<>"")*(D16:D19<=D15:D18))>0,"Etapy muszą być w kolejności chronologicznej",IF(D20="","Uzupełnij datę powrotu przez granicę",IF(D20<=MAX(D15:D19),"Powrót przez granicę musi być po ostatnim wjeździe",IF(SUM((E15:G19>IFERROR(ROUNDUP(I24:I28,0),1000000000))*1)>0,"Więcej posiłków niż dni pobytu w kraju – sprawdź śniadania, obiady i kolacje",IF(K7="","Uzupełnij datę kursu",IF(SUMPRODUCT(('Kursy NBP'!$F$8:$F$17<>"")*((('Kursy NBP'!$G$8:$G$17="")+('Kursy NBP'!$H$8:$H$17=""))>0))>0,"Kurs ręczny: uzupełnij datę notowania i nr tabeli (arkusz Kursy NBP)",IF(COUNTIF(M24:M28,"brak kursu")>0,"Brak kursu NBP – sprawdź datę kursu i internet albo wpisz kurs ręcznie (arkusz Kursy NBP)","OK")))))))))))} -> OK | I1: {="Do wypłaty – dieta"&IF($E$1<>"OK","",IFERROR(" ("&_xlfn.TEXTJOIN(" + ",TRUE,_xlfn._xlws.FILTER(FIXED(C33:C42,2)&" "&B33:B42,C33:C42<>0))&")",""))} -> Do wypłaty – dieta (215,53 EUR) | K1: ="Wydatki (z zaliczki na wydatki)" -> Wydatki (z zaliczki na wydatki) | M1: ="Ogółem do rozliczenia" -> Ogółem do rozliczenia
B2: ver. 2.5 (09.10.2026) · wg rozporządzenia MPiPS z 29.01.2013 (t.j. Dz.U. 2023 poz. 2190) · kursy NBP pobierane automatycznie | I2: =IF($E$1<>"OK","—",M29) -> 930.46 | K2: =IF($E$1<>"OK","—",F51-M29) -> 1640.5 | M2: =IF($E$1<>"OK","—",F51) -> 2570.96
B3: Legenda: | C3: wymagane | D3: do wpisania (opcjonalne) | E3: liczy się samo | F3: błąd w danych
B4: 1. Dane podróży i polecenia wyjazdu
B5: Pracownik (imię i nazwisko) | C5: Jan Kowalski | I5: Wyjazd z miejscowości (data i godz.) | K5: 46279.229
B6: Stanowisko służbowe | C6: Serwisant | I6: Powrót do miejscowości (data i godz.) | K6: 46283.917
B7: Cel podróży / zlecenie serwisowe | C7: Serwis linii pakującej – klient w Monachium i Linzu | I7: Data kursu NBP | K7: 46275
B8: Nr polecenia wyjazdu | C8: 1/2026 | I8: Kurs NBP z dnia | K8: dzień przed datą kursu
B9: Data polecenia (z dnia) | C9: 46275 | I9: Pobrana zaliczka (zł)
B10: Miejscowość wyjazdu i powrotu | C10: Poznań | I10: Termin rozliczenia zaliczki (dni)
B11: Środki lokomocji | C11: samochód służbowy | I11: Liczba załączonych dowodów
B13: 2. Pobyt za granicą – kraj, wjazd i zapewnione posiłki (dieta) | H13: Miejscowość i godziny (do druku delegacji) | K13: Przejazd (do rachunku kosztów)
B14: Etap | C14: Kraj | D14: Wjazd do kraju (data i godz.) | E14: Śniadania (szt.) | F14: Obiady (szt.) | G14: Kolacje (szt.) | H14: Miejscowość | I14: Przyjazd (data i godz.) | J14: Wyjazd (data i godz.) | K14: Środek lokomocji | L14: Koszt | M14: Waluta | N14: Koszt (PLN)
B15: Etap 1 | C15: Niemcy | D15: 46279.438 | E15: 2 | F15: 0 | G15: 0 | H15: Monachium | I15: 46279.51 | J15: 46281.375 | M15: PLN | N15: =IF(N(L15)=0,"",IF(OR(M15="",M15="PLN"),L15,IFERROR(ROUND(L15*_xlfn.XLOOKUP(M15,'Kursy NBP'!$B$8:$B$17,'Kursy NBP'!$C$8:$C$17),2),"brak kursu")))
B16: Etap 2 | C16: Austria | D16: 46281.583 | E16: 2 | F16: 0 | G16: 0 | H16: Linz | I16: 46281.646 | J16: 46283.583 | M16: PLN | N16: =IF(N(L16)=0,"",IF(OR(M16="",M16="PLN"),L16,IFERROR(ROUND(L16*_xlfn.XLOOKUP(M16,'Kursy NBP'!$B$8:$B$17,'Kursy NBP'!$C$8:$C$17),2),"brak kursu")))
B17: Etap 3 | M17: PLN | N17: =IF(N(L17)=0,"",IF(OR(M17="",M17="PLN"),L17,IFERROR(ROUND(L17*_xlfn.XLOOKUP(M17,'Kursy NBP'!$B$8:$B$17,'Kursy NBP'!$C$8:$C$17),2),"brak kursu")))
B18: Etap 4 | M18: PLN | N18: =IF(N(L18)=0,"",IF(OR(M18="",M18="PLN"),L18,IFERROR(ROUND(L18*_xlfn.XLOOKUP(M18,'Kursy NBP'!$B$8:$B$17,'Kursy NBP'!$C$8:$C$17),2),"brak kursu")))
B19: Etap 5 | M19: PLN | N19: =IF(N(L19)=0,"",IF(OR(M19="",M19="PLN"),L19,IFERROR(ROUND(L19*_xlfn.XLOOKUP(M19,'Kursy NBP'!$B$8:$B$17,'Kursy NBP'!$C$8:$C$17),2),"brak kursu")))
B20: Powrót | C20: Polska | D20: 46283.698 | E20: koniec pobytu za granicą (§12) | M20: PLN | N20: =IF(N(L20)=0,"",IF(OR(M20="",M20="PLN"),L20,IFERROR(ROUND(L20*_xlfn.XLOOKUP(M20,'Kursy NBP'!$B$8:$B$17,'Kursy NBP'!$C$8:$C$17),2),"brak kursu")))
B22: 3. Wyliczenie diety (automatycznie)
B23: Etap | C23: Kraj | D23: Waluta | E23: Dieta za dobę | F23: Od | G23: Do | H23: Czas (godz.) | I23: Liczba diet | J23: Potrącenie za posiłki | K23: Dieta należna (waluta) | L23: Kurs NBP | M23: Dieta należna (PLN)
B24: Etap 1 | C24: =IF(C15="","",C15) -> Niemcy | D24: =IF(C15="","",_xlfn.XLOOKUP(C15,Kraje!$A$2:$A$121,Kraje!$B$2:$B$121,"?")) -> EUR | E24: =IF(C15="","",_xlfn.XLOOKUP(C15,Kraje!$A$2:$A$121,Kraje!$C$2:$C$121,0)) -> 49 | F24: =IF(C15="","",D15) -> 46279.438 | G24: =IF(C15="","",IF(C16<>"",D16,$D$20)) -> 46281.583 | H24: =IF(C15="","",IFERROR(MAX(0,ROUND((G24-F24)*1440,0)/60),0)) -> 51.5 | I24: =IF(C15="","",_xlfn.LET(_xlpm.h,H24,_xlpm.d,INT(_xlpm.h/24),_xlpm.reszta,_xlpm.h-24*_xlpm.d,_xlpm.d+IF(_xlpm.reszta=0,0,IF(_xlpm.reszta<=8,1/3,IF(_xlpm.reszta<=12,1/2,1))))) -> 2.3333333 | J24: =IF(C15="","",ROUND(E24*(N(E15)*Parametry!$C$3+N(F15)*Parametry!$C$4+N(G15)*Parametry!$C$5),2)) -> 14.7 | K24: =IF(C15="","",MAX(0,ROUND(E24*I24-J24,2))) -> 99.63 | L24: =IF(C15="","",_xlfn.XLOOKUP(D24,'Kursy NBP'!$B$8:$B$17,'Kursy NBP'!$C$8:$C$17,"brak kursu")) -> 4.3171 | M24: =IF(C15="","",IF(ISNUMBER(L24),ROUND(K24*L24,2),"brak kursu")) -> 430.11
B25: Etap 2 | C25: =IF(C16="","",C16) -> Austria | D25: =IF(C16="","",_xlfn.XLOOKUP(C16,Kraje!$A$2:$A$121,Kraje!$B$2:$B$121,"?")) -> EUR | E25: =IF(C16="","",_xlfn.XLOOKUP(C16,Kraje!$A$2:$A$121,Kraje!$C$2:$C$121,0)) -> 57 | F25: =IF(C16="","",D16) -> 46281.583 | G25: =IF(C16="","",IF(C17<>"",D17,$D$20)) -> 46283.698 | H25: =IF(C16="","",IFERROR(MAX(0,ROUND((G25-F25)*1440,0)/60),0)) -> 50.75 | I25: =IF(C16="","",_xlfn.LET(_xlpm.h,H25,_xlpm.d,INT(_xlpm.h/24),_xlpm.reszta,_xlpm.h-24*_xlpm.d,_xlpm.d+IF(_xlpm.reszta=0,0,IF(_xlpm.reszta<=8,1/3,IF(_xlpm.reszta<=12,1/2,1))))) -> 2.3333333 | J25: =IF(C16="","",ROUND(E25*(N(E16)*Parametry!$C$3+N(F16)*Parametry!$C$4+N(G16)*Parametry!$C$5),2)) -> 17.1 | K25: =IF(C16="","",MAX(0,ROUND(E25*I25-J25,2))) -> 115.9 | L25: =IF(C16="","",_xlfn.XLOOKUP(D25,'Kursy NBP'!$B$8:$B$17,'Kursy NBP'!$C$8:$C$17,"brak kursu")) -> 4.3171 | M25: =IF(C16="","",IF(ISNUMBER(L25),ROUND(K25*L25,2),"brak kursu")) -> 500.35
B26: Etap 3 | C26: =IF(C17="","",C17) | D26: =IF(C17="","",_xlfn.XLOOKUP(C17,Kraje!$A$2:$A$121,Kraje!$B$2:$B$121,"?")) | E26: =IF(C17="","",_xlfn.XLOOKUP(C17,Kraje!$A$2:$A$121,Kraje!$C$2:$C$121,0)) | F26: =IF(C17="","",D17) | G26: =IF(C17="","",IF(C18<>"",D18,$D$20)) | H26: =IF(C17="","",IFERROR(MAX(0,ROUND((G26-F26)*1440,0)/60),0)) | I26: =IF(C17="","",_xlfn.LET(_xlpm.h,H26,_xlpm.d,INT(_xlpm.h/24),_xlpm.reszta,_xlpm.h-24*_xlpm.d,_xlpm.d+IF(_xlpm.reszta=0,0,IF(_xlpm.reszta<=8,1/3,IF(_xlpm.reszta<=12,1/2,1))))) | J26: =IF(C17="","",ROUND(E26*(N(E17)*Parametry!$C$3+N(F17)*Parametry!$C$4+N(G17)*Parametry!$C$5),2)) | K26: =IF(C17="","",MAX(0,ROUND(E26*I26-J26,2))) | L26: =IF(C17="","",_xlfn.XLOOKUP(D26,'Kursy NBP'!$B$8:$B$17,'Kursy NBP'!$C$8:$C$17,"brak kursu")) | M26: =IF(C17="","",IF(ISNUMBER(L26),ROUND(K26*L26,2),"brak kursu"))
B27: Etap 4 | C27: =IF(C18="","",C18) | D27: =IF(C18="","",_xlfn.XLOOKUP(C18,Kraje!$A$2:$A$121,Kraje!$B$2:$B$121,"?")) | E27: =IF(C18="","",_xlfn.XLOOKUP(C18,Kraje!$A$2:$A$121,Kraje!$C$2:$C$121,0)) | F27: =IF(C18="","",D18) | G27: =IF(C18="","",IF(C19<>"",D19,$D$20)) | H27: =IF(C18="","",IFERROR(MAX(0,ROUND((G27-F27)*1440,0)/60),0)) | I27: =IF(C18="","",_xlfn.LET(_xlpm.h,H27,_xlpm.d,INT(_xlpm.h/24),_xlpm.reszta,_xlpm.h-24*_xlpm.d,_xlpm.d+IF(_xlpm.reszta=0,0,IF(_xlpm.reszta<=8,1/3,IF(_xlpm.reszta<=12,1/2,1))))) | J27: =IF(C18="","",ROUND(E27*(N(E18)*Parametry!$C$3+N(F18)*Parametry!$C$4+N(G18)*Parametry!$C$5),2)) | K27: =IF(C18="","",MAX(0,ROUND(E27*I27-J27,2))) | L27: =IF(C18="","",_xlfn.XLOOKUP(D27,'Kursy NBP'!$B$8:$B$17,'Kursy NBP'!$C$8:$C$17,"brak kursu")) | M27: =IF(C18="","",IF(ISNUMBER(L27),ROUND(K27*L27,2),"brak kursu"))
B28: Etap 5 | C28: =IF(C19="","",C19) | D28: =IF(C19="","",_xlfn.XLOOKUP(C19,Kraje!$A$2:$A$121,Kraje!$B$2:$B$121,"?")) | E28: =IF(C19="","",_xlfn.XLOOKUP(C19,Kraje!$A$2:$A$121,Kraje!$C$2:$C$121,0)) | F28: =IF(C19="","",D19) | G28: =IF(C19="","",$D$20) | H28: =IF(C19="","",IFERROR(MAX(0,ROUND((G28-F28)*1440,0)/60),0)) | I28: =IF(C19="","",_xlfn.LET(_xlpm.h,H28,_xlpm.d,INT(_xlpm.h/24),_xlpm.reszta,_xlpm.h-24*_xlpm.d,_xlpm.d+IF(_xlpm.reszta=0,0,IF(_xlpm.reszta<=8,1/3,IF(_xlpm.reszta<=12,1/2,1))))) | J28: =IF(C19="","",ROUND(E28*(N(E19)*Parametry!$C$3+N(F19)*Parametry!$C$4+N(G19)*Parametry!$C$5),2)) | K28: =IF(C19="","",MAX(0,ROUND(E28*I28-J28,2))) | L28: =IF(C19="","",_xlfn.XLOOKUP(D28,'Kursy NBP'!$B$8:$B$17,'Kursy NBP'!$C$8:$C$17,"brak kursu")) | M28: =IF(C19="","",IF(ISNUMBER(L28),ROUND(K28*L28,2),"brak kursu"))
B29: DIETA RAZEM (PLN) | M29: =SUM(M24:M28) -> 930.46
B31: 4. Dieta według walut
B32: Waluta | C32: Dieta (waluta) | D32: Kurs NBP | E32: Dieta (PLN)
B33: EUR | C33: =SUMIF($D$24:$D$28,B33,$K$24:$K$28) -> 215.53 | D33: =IF(C33=0,"",_xlfn.XLOOKUP(B33,'Kursy NBP'!$B$8:$B$17,'Kursy NBP'!$C$8:$C$17,"brak kursu")) -> 4.3171 | E33: =IF(D33="",0,IF(ISNUMBER(D33),ROUND(C33*D33,2),"brak kursu")) -> 930.46
B34: USD | C34: =SUMIF($D$24:$D$28,B34,$K$24:$K$28) -> 0 | D34: =IF(C34=0,"",_xlfn.XLOOKUP(B34,'Kursy NBP'!$B$8:$B$17,'Kursy NBP'!$C$8:$C$17,"brak kursu")) | E34: =IF(D34="",0,IF(ISNUMBER(D34),ROUND(C34*D34,2),"brak kursu")) -> 0
B35: AUD | C35: =SUMIF($D$24:$D$28,B35,$K$24:$K$28) -> 0 | D35: =IF(C35=0,"",_xlfn.XLOOKUP(B35,'Kursy NBP'!$B$8:$B$17,'Kursy NBP'!$C$8:$C$17,"brak kursu")) | E35: =IF(D35="",0,IF(ISNUMBER(D35),ROUND(C35*D35,2),"brak kursu")) -> 0
B36: DKK | C36: =SUMIF($D$24:$D$28,B36,$K$24:$K$28) -> 0 | D36: =IF(C36=0,"",_xlfn.XLOOKUP(B36,'Kursy NBP'!$B$8:$B$17,'Kursy NBP'!$C$8:$C$17,"brak kursu")) | E36: =IF(D36="",0,IF(ISNUMBER(D36),ROUND(C36*D36,2),"brak kursu")) -> 0
B37: JPY | C37: =SUMIF($D$24:$D$28,B37,$K$24:$K$28) -> 0 | D37: =IF(C37=0,"",_xlfn.XLOOKUP(B37,'Kursy NBP'!$B$8:$B$17,'Kursy NBP'!$C$8:$C$17,"brak kursu")) | E37: =IF(D37="",0,IF(ISNUMBER(D37),ROUND(C37*D37,2),"brak kursu")) -> 0
B38: CAD | C38: =SUMIF($D$24:$D$28,B38,$K$24:$K$28) -> 0 | D38: =IF(C38=0,"",_xlfn.XLOOKUP(B38,'Kursy NBP'!$B$8:$B$17,'Kursy NBP'!$C$8:$C$17,"brak kursu")) | E38: =IF(D38="",0,IF(ISNUMBER(D38),ROUND(C38*D38,2),"brak kursu")) -> 0
B39: NOK | C39: =SUMIF($D$24:$D$28,B39,$K$24:$K$28) -> 0 | D39: =IF(C39=0,"",_xlfn.XLOOKUP(B39,'Kursy NBP'!$B$8:$B$17,'Kursy NBP'!$C$8:$C$17,"brak kursu")) | E39: =IF(D39="",0,IF(ISNUMBER(D39),ROUND(C39*D39,2),"brak kursu")) -> 0
B40: CHF | C40: =SUMIF($D$24:$D$28,B40,$K$24:$K$28) -> 0 | D40: =IF(C40=0,"",_xlfn.XLOOKUP(B40,'Kursy NBP'!$B$8:$B$17,'Kursy NBP'!$C$8:$C$17,"brak kursu")) | E40: =IF(D40="",0,IF(ISNUMBER(D40),ROUND(C40*D40,2),"brak kursu")) -> 0
B41: SEK | C41: =SUMIF($D$24:$D$28,B41,$K$24:$K$28) -> 0 | D41: =IF(C41=0,"",_xlfn.XLOOKUP(B41,'Kursy NBP'!$B$8:$B$17,'Kursy NBP'!$C$8:$C$17,"brak kursu")) | E41: =IF(D41="",0,IF(ISNUMBER(D41),ROUND(C41*D41,2),"brak kursu")) -> 0
B42: GBP | C42: =SUMIF($D$24:$D$28,B42,$K$24:$K$28) -> 0 | D42: =IF(C42=0,"",_xlfn.XLOOKUP(B42,'Kursy NBP'!$B$8:$B$17,'Kursy NBP'!$C$8:$C$17,"brak kursu")) | E42: =IF(D42="",0,IF(ISNUMBER(D42),ROUND(C42*D42,2),"brak kursu")) -> 0
B44: 5. Pozostałe koszty podróży (do rachunku kosztów w arkuszu „Delegacja”)
...

Sheet Raport
B2: Rozliczenie diety z tytułu zagranicznej podróży służbowej
B3: wg rozporządzenia MPiPS z 29.01.2013 (t.j. Dz.U. 2023 poz. 2190) · kursy średnie NBP (tabela A)
B4: =IF(Kalkulator!E1="OK","","UWAGA: "&Kalkulator!E1)
B6: Dane podróży
B7: Pracownik: | E7: =IF(Kalkulator!C5="","",Kalkulator!C5) -> Jan Kowalski
B8: Cel podróży: | E8: =IF(Kalkulator!C7="","",Kalkulator!C7) -> Serwis linii pakującej – klient w Monachium i Linzu
B9: Kraj docelowy: | E9: {=IFERROR(_xlfn.TEXTJOIN(", ",TRUE,_xlfn.UNIQUE(_xlfn._xlws.FILTER(Kalkulator!C15:C19,Kalkulator!C15:C19<>""))),"")} -> Niemcy, Austria
B10: Data i godzina rozpoczęcia: | E10: =IF(Kalkulator!D15="","",Kalkulator!D15) -> 46279.438
B11: Data i godzina zakończenia: | E11: =IF(Kalkulator!D20="","",Kalkulator!D20) -> 46283.698
B12: Czas podróży: | E12: =IF(OR(Kalkulator!D15="",Kalkulator!D20=""),"",_xlfn.LET(_xlpm.m,ROUND((Kalkulator!D20-Kalkulator!D15)*1440,0),_xlpm.d,INT(_xlpm.m/1440),_xlpm.h,INT(MOD(_xlpm.m,1440)/60),_xlpm.mi,MOD(_xlpm.m,60),_xlpm.d&IF(_xlpm.d=1," dzień "," dni ")&_xlpm.h&" godz. "&_xlpm.mi&" min")) -> 4 dni 6 godz. 15 min
B14: Diety
B15: Kraj | C15: Od | D15: Do | E15: Czas pobytu | F15: Dieta za dobę | G15: Liczba diet | H15: Wysokość diet | I15: Potrącenie za posiłki | J15: Należna dieta | K15: Waluta
B16: =IF(Kalkulator!$C24="","",Kalkulator!C24) -> Niemcy | C16: =IF(Kalkulator!$C24="","",Kalkulator!F24) -> 46279.438 | D16: =IF(Kalkulator!$C24="","",Kalkulator!G24) -> 46281.583 | E16: =IF(Kalkulator!$C24="","",_xlfn.LET(_xlpm.m,ROUND(Kalkulator!H24*60,0),_xlpm.d,INT(_xlpm.m/1440),_xlpm.h,INT(MOD(_xlpm.m,1440)/60),_xlpm.mi,MOD(_xlpm.m,60),_xlpm.d&IF(_xlpm.d=1," dzień "," dni ")&_xlpm.h&" godz."&IF(_xlpm.mi>0," "&_xlpm.mi&" min",""))) -> 2 dni 3 godz. 30 min | F16: =IF(Kalkulator!$C24="","",Kalkulator!E24) -> 49 | G16: =IF(Kalkulator!$C24="","",Kalkulator!I24) -> 2.3333333 | H16: =IF(Kalkulator!$C24="","",ROUND(Kalkulator!E24*Kalkulator!I24,2)) -> 114.33 | I16: =IF(Kalkulator!$C24="","",Kalkulator!J24) -> 14.7 | J16: =IF(Kalkulator!$C24="","",Kalkulator!K24) -> 99.63 | K16: =IF(Kalkulator!$C24="","",Kalkulator!D24) -> EUR
B17: =IF(Kalkulator!$C25="","",Kalkulator!C25) -> Austria | C17: =IF(Kalkulator!$C25="","",Kalkulator!F25) -> 46281.583 | D17: =IF(Kalkulator!$C25="","",Kalkulator!G25) -> 46283.698 | E17: =IF(Kalkulator!$C25="","",_xlfn.LET(_xlpm.m,ROUND(Kalkulator!H25*60,0),_xlpm.d,INT(_xlpm.m/1440),_xlpm.h,INT(MOD(_xlpm.m,1440)/60),_xlpm.mi,MOD(_xlpm.m,60),_xlpm.d&IF(_xlpm.d=1," dzień "," dni ")&_xlpm.h&" godz."&IF(_xlpm.mi>0," "&_xlpm.mi&" min",""))) -> 2 dni 2 godz. 45 min | F17: =IF(Kalkulator!$C25="","",Kalkulator!E25) -> 57 | G17: =IF(Kalkulator!$C25="","",Kalkulator!I25) -> 2.3333333 | H17: =IF(Kalkulator!$C25="","",ROUND(Kalkulator!E25*Kalkulator!I25,2)) -> 133 | I17: =IF(Kalkulator!$C25="","",Kalkulator!J25) -> 17.1 | J17: =IF(Kalkulator!$C25="","",Kalkulator!K25) -> 115.9 | K17: =IF(Kalkulator!$C25="","",Kalkulator!D25) -> EUR
B18: =IF(Kalkulator!$C26="","",Kalkulator!C26) | C18: =IF(Kalkulator!$C26="","",Kalkulator!F26) | D18: =IF(Kalkulator!$C26="","",Kalkulator!G26) | E18: =IF(Kalkulator!$C26="","",_xlfn.LET(_xlpm.m,ROUND(Kalkulator!H26*60,0),_xlpm.d,INT(_xlpm.m/1440),_xlpm.h,INT(MOD(_xlpm.m,1440)/60),_xlpm.mi,MOD(_xlpm.m,60),_xlpm.d&IF(_xlpm.d=1," dzień "," dni ")&_xlpm.h&" godz."&IF(_xlpm.mi>0," "&_xlpm.mi&" min",""))) | F18: =IF(Kalkulator!$C26="","",Kalkulator!E26) | G18: =IF(Kalkulator!$C26="","",Kalkulator!I26) | H18: =IF(Kalkulator!$C26="","",ROUND(Kalkulator!E26*Kalkulator!I26,2)) | I18: =IF(Kalkulator!$C26="","",Kalkulator!J26) | J18: =IF(Kalkulator!$C26="","",Kalkulator!K26) | K18: =IF(Kalkulator!$C26="","",Kalkulator!D26)
B19: =IF(Kalkulator!$C27="","",Kalkulator!C27) | C19: =IF(Kalkulator!$C27="","",Kalkulator!F27) | D19: =IF(Kalkulator!$C27="","",Kalkulator!G27) | E19: =IF(Kalkulator!$C27="","",_xlfn.LET(_xlpm.m,ROUND(Kalkulator!H27*60,0),_xlpm.d,INT(_xlpm.m/1440),_xlpm.h,INT(MOD(_xlpm.m,1440)/60),_xlpm.mi,MOD(_xlpm.m,60),_xlpm.d&IF(_xlpm.d=1," dzień "," dni ")&_xlpm.h&" godz."&IF(_xlpm.mi>0," "&_xlpm.mi&" min",""))) | F19: =IF(Kalkulator!$C27="","",Kalkulator!E27) | G19: =IF(Kalkulator!$C27="","",Kalkulator!I27) | H19: =IF(Kalkulator!$C27="","",ROUND(Kalkulator!E27*Kalkulator!I27,2)) | I19: =IF(Kalkulator!$C27="","",Kalkulator!J27) | J19: =IF(Kalkulator!$C27="","",Kalkulator!K27) | K19: =IF(Kalkulator!$C27="","",Kalkulator!D27)
B20: =IF(Kalkulator!$C28="","",Kalkulator!C28) | C20: =IF(Kalkulator!$C28="","",Kalkulator!F28) | D20: =IF(Kalkulator!$C28="","",Kalkulator!G28) | E20: =IF(Kalkulator!$C28="","",_xlfn.LET(_xlpm.m,ROUND(Kalkulator!H28*60,0),_xlpm.d,INT(_xlpm.m/1440),_xlpm.h,INT(MOD(_xlpm.m,1440)/60),_xlpm.mi,MOD(_xlpm.m,60),_xlpm.d&IF(_xlpm.d=1," dzień "," dni ")&_xlpm.h&" godz."&IF(_xlpm.mi>0," "&_xlpm.mi&" min",""))) | F20: =IF(Kalkulator!$C28="","",Kalkulator!E28) | G20: =IF(Kalkulator!$C28="","",Kalkulator!I28) | H20: =IF(Kalkulator!$C28="","",ROUND(Kalkulator!E28*Kalkulator!I28,2)) | I20: =IF(Kalkulator!$C28="","",Kalkulator!J28) | J20: =IF(Kalkulator!$C28="","",Kalkulator!K28) | K20: =IF(Kalkulator!$C28="","",Kalkulator!D28)
B22: Koszty podróży
B23: Należne diety w walucie: | E23: {=IFERROR(_xlfn.TEXTJOIN("; ",TRUE,_xlfn._xlws.FILTER(FIXED(Kalkulator!$C$33:$C$42,2)&" "&Kalkulator!$B$33:$B$42,Kalkulator!$C$33:$C$42<>0)),"")} -> 215,53 EUR
B24: Kurs średni NBP: | E24: {=IFERROR(_xlfn.TEXTJOIN("; ",TRUE,_xlfn._xlws.FILTER(_xlfn.LET(_xlpm.w,Kalkulator!$B$33:$B$42,_xlpm.k,Kalkulator!$D$33:$D$42,_xlpm.d,_xlfn.XLOOKUP(_xlpm.w,'Kursy NBP'!$B$8:$B$17,'Kursy NBP'!$D$8:$D$17),_xlpm.n,_xlfn.XLOOKUP(_xlpm.w,'Kursy NBP'!$B$8:$B$17,'Kursy NBP'!$E$8:$E$17),"1 "&_xlpm.w&" = "&IF(ISNUMBER(_xlpm.k),FIXED(_xlpm.k,IF(_xlpm.k<0.1,6,4),TRUE),"brak kursu")&" PLN (tab. "&_xlpm.n&" z "&RIGHT("0"&DAY(_xlpm.d),2)&"."&RIGHT("0"&MONTH(_xlpm.d),2)&"."&YEAR(_xlpm.d)&")"),Kalkulator!$C$33:$C$42<>0)),"")} -> 1 EUR = 4,3171 PLN (tab. 175/A/NBP/2026 z 09.09.2026)
B25: Koszt całkowity w PLN: | E25: =Kalkulator!M29 -> 930.46
B28: ="Kurs NBP z "&IF(Kalkulator!K8="w dniu daty kursu","dnia ","ostatniego dnia roboczego przed dniem ")&IF(Kalkulator!K7="","-",RIGHT("0"&DAY(Kalkulator!K7),2)&"."&RIGHT("0"&MONTH(Kalkulator!K7),2)&"."&YEAR(Kalkulator!K7))&". Dieta liczona wg §13–14 rozporządzenia, osobno dla każdego kraju." -> Kurs NBP z ostatniego dnia roboczego przed dniem 10.09.2026. Dieta liczona wg §13–14 rozporządzenia, osobno dla każdego kraju.
B29: ="Data sporządzenia: "&RIGHT("0"&DAY(TODAY()),2)&"."&RIGHT("0"&MONTH(TODAY()),2)&"."&YEAR(TODAY()) -> Data sporządzenia: 09.10.2026

Sheet Delegacja
B1: {=IF(Kalkulator!E1<>"OK","UWAGA: "&Kalkulator!E1,IF(AND(Kalkulator!$K$5<>"",Kalkulator!$K$5>Kalkulator!$D$15),"UWAGA: wyjazd z miejscowości jest po przekroczeniu granicy",IF(AND(Kalkulator!$K$6<>"",Kalkulator!$K$6<Kalkulator!$D$20),"UWAGA: powrót do miejscowości jest przed przekroczeniem granicy",IF(COUNTIF(Kalkulator!$N$15:$N$20,"brak kursu")+COUNTIF(Kalkulator!$F$46:$F$50,"brak kursu")>0,"UWAGA: brak kursu NBP dla waluty kosztu – sprawdź datę kursu",IF(SUMPRODUCT((Kalkulator!$I$15:$I$19<>"")*(Kalkulator!$I$15:$I$19<Kalkulator!$D$15:$D$19))+SUMPRODUCT((Kalkulator!$J$15:$J$19<>"")*((Kalkulator!$J$15:$J$19<IF(Kalkulator!$I$15:$I$19<>"",Kalkulator!$I$15:$I$19,Kalkulator!$D$15:$D$19))+(Kalkulator!$J$15:$J$19>IF(Kalkulator!$C$16:$C$20<>"",Kalkulator!$D$16:$D$20,Kalkulator!$D$20))))>0,"UWAGA: godziny przyjazdu/wyjazdu z miejscowości nie zgadzają się z przekroczeniami granic – zobacz czerwone pola w Kalkulatorze","")))))}
F2: STWIERDZENIE POBYTU SŁUŻBOWEGO
B5: Pieczątka wysyłającego
B6: POLECENIE WYJAZDU
B7: ="SŁUŻBOWEGO Nr "&IF(Kalkulator!$C$8="",". . . . . . . . ",Kalkulator!$C$8) -> SŁUŻBOWEGO Nr 1/2026
B8: ="z dnia "&IF(Kalkulator!$C$9="",". . . . . . . . . . . . . . ",RIGHT("0"&DAY(Kalkulator!$C$9),2)&"."&RIGHT("0"&MONTH(Kalkulator!$C$9),2)&"."&YEAR(Kalkulator!$C$9)) -> z dnia 10.09.2026
B10: ="dla "&IF(Kalkulator!$C$5="",". . . . . . . . . . . . . . . . . . . . . . . . . . . . . . . . . . . . . . . . ",Kalkulator!$C$5) -> dla Jan Kowalski
B11: (imię i nazwisko)
B12: =IF(Kalkulator!$C$6="",". . . . . . . . . . . . . . . . . . . . . . . . . . . . . . . . . . . . . . . . . . . . ",Kalkulator!$C$6) -> Serwisant
B13: (stanowisko służbowe)
B14: {="do "&IFERROR(_xlfn.TEXTJOIN(", ",TRUE,_xlfn.UNIQUE(_xlfn._xlws.FILTER(IF(Kalkulator!$H$15:$H$19<>"",Kalkulator!$H$15:$H$19,Kalkulator!$C$15:$C$19),Kalkulator!$C$15:$C$19<>""))),". . . . . . . . . . . . . . . . . . . . . . . . . . . . . . . . . . . . . . . . ")} -> do Monachium, Linz
B15: ="na czas od "&IF(OR(IF(Kalkulator!$K$5="",Kalkulator!$D$15,Kalkulator!$K$5)="",IF(Kalkulator!$K$5="",Kalkulator!$D$15,Kalkulator!$K$5)=0),". . . . . . . . . . ",RIGHT("0"&DAY(IF(Kalkulator!$K$5="",Kalkulator!$D$15,Kalkulator!$K$5)),2)&"."&RIGHT("0"&MONTH(IF(Kalkulator!$K$5="",Kalkulator!$D$15,Kalkulator!$K$5)),2)&"."&YEAR(IF(Kalkulator!$K$5="",Kalkulator!$D$15,Kalkulator!$K$5)))&" do "&IF(OR(IF(Kalkulator!$K$6="",Kalkulator!$D$20,Kalkulator!$K$6)="",IF(Kalkulator!$K$6="",Kalkulator!$D$20,Kalkulator!$K$6)=0),". . . . . . . . . . ",RIGHT("0"&DAY(IF(Kalkulator!$K$6="",Kalkulator!$D$20,Kalkulator!$K$6)),2)&"."&RIGHT("0"&MONTH(IF(Kalkulator!$K$6="",Kalkulator!$D$20,Kalkulator!$K$6)),2)&"."&YEAR(IF(Kalkulator!$K$6="",Kalkulator!$D$20,Kalkulator!$K$6))) -> na czas od 14.09.2026 do 18.09.2026
B16: ="w celu "&IF(Kalkulator!$C$7="",". . . . . . . . . . . . . . . . . . . . . . . . . . . . . . . . . . . . . . . . ",Kalkulator!$C$7) -> w celu Serwis linii pakującej – klient w Monachium i Linzu
B17: środki lokomocji
B18: =IF(Kalkulator!$C$11="",". . . . . . . . . . . . . . . . . . . . . . . . . . . . . . ",Kalkulator!$C$11) -> samochód służbowy
B20: . . . . . . . | C20: . . . . . . . . . . . .
B21: data | C21: podpis wysyłającego
B25: {="Proszę o wypłacenie zaliczki w kwocie zł "&IF(N(Kalkulator!$K$9)=0,". . . . . . . . ",FIXED(Kalkulator!$K$9,2))&" słownie zł "&IF(N(Kalkulator!$K$9)=0,". . . . . . . . . . . . . . . . . . . . . . . . . . . . . . ",_xlfn.LET(_xlpm.x,ROUND(ABS(Kalkulator!$K$9),2),_xlpm.z,INT(_xlpm.x),_xlpm.g,ROUND((_xlpm.x-_xlpm.z)*100,0),_xlpm.tri,_xlfn.LAMBDA(_xlpm.v,_xlfn.LET(_xlpm.h,INT(_xlpm.v/100),_xlpm.t,INT(MOD(_xlpm.v,100)/10),_xlpm.u,MOD(_xlpm.v,10),INDEX({"","sto","dwieście","trzysta","czterysta","pięćset","sześćset","siedemset","osiemset","dziewięćset"},_xlpm.h+1)&" "&IF(_xlpm.t=1,INDEX({"dziesięć","jedenaście","dwanaście","trzynaście","czternaście","piętnaście","szesnaście","siedemnaście","osiemnaście","dziewiętnaście"},_xlpm.u+1),INDEX({"","","dwadzieścia","trzydzieści","czterdzieści","pięćdziesiąt","sześćdziesiąt","siedemdziesiąt","osiemdziesiąt","dziewięćdziesiąt"},_xlpm.t+1)&" "&INDEX({"","jeden","dwa","trzy","cztery","pięć","sześć","siedem","osiem","dziewięć"},_xlpm.u+1)))),_xlpm.grp,_xlfn.LAMBDA(_xlpm.v,_xlpm.jd,_xlpm.dw,_xlpm.wl,IF(_xlpm.v=0,"",IF(_xlpm.v=1,_xlpm.jd,_xlpm.tri(_xlpm.v)&" "&IF(AND(MOD(_xlpm.v,10)>=2,MOD(_xlpm.v,10)<=4,OR(MOD(_xlpm.v,100)<10,MOD(_xlpm.v,100)>20)),_xlpm.dw,_xlpm.wl)))),_xlpm.s,TRIM(_xlpm.grp(INT(_xlpm.z/10^6),"jeden milion","miliony","milionów")&" "&_xlpm.grp(INT(MOD(_xlpm.z,10^6)/1000),"jeden tysiąc","tysiące","tysięcy")&" "&_xlpm.tri(MOD(_xlpm.z,1000))),IF(_xlpm.z=0,"zero",_xlpm.s)&" "&RIGHT("0"&_xlpm.g,2)&"/100"))} -> Proszę o wypłacenie zaliczki w kwocie zł . . . . . . . . słownie zł . . . . . . . . . . . . . . . . . . . . . . . . . . . . . .
B26: ="na pokrycie wydatków zgodnie z poleceniem wyjazdu służbowego nr "&IF(Kalkulator!$C$8="",". . . . . . . . . . ",Kalkulator!$C$8) -> na pokrycie wydatków zgodnie z poleceniem wyjazdu służbowego nr 1/2026
H28: . . . . . . . . . . . .
H29: Podpis delegowanego
B31: Zatwierdzono na zł . . . . . . . . słownie zł . . . . . . . . . . . . . . . . . . . . . . . . . . . . . . . . . . . . . . . .
B32: do wypłaty z sum . . . . . . . . . . . . . .
G34: Konto | I34: Nr dowodu
B35: Część | C35: Dział | D35: Rozdział | E35: § | F35: Poz. | G35: Wn | H35: Ma
F38: . . . . . . . | G38: . . . . . . . . . . . . . .
F39: data | G39: podpisy sprawdzających
I40: str. 1
B41: RACHUNEK KOSZTÓW PODRÓŻY
B43: W Y J A Z D | E43: P R Z Y J A Z D | H43: Środki lokomocji*) | I43: Koszty przejazdu
B44: miejscowość | C44: data | D44: godz. | E44: miejscowość | F44: data | G44: godz. | I44: zł i gr
B45: {=_xlfn.LET(_xlpm.n,COUNTIF(Kalkulator!$C$15:$C$19,"?*"),_xlpm.i,1,_xlpm.p,IF(Kalkulator!$H$15:$H$19<>"",Kalkulator!$H$15:$H$19,Kalkulator!$C$15:$C$19),_xlpm.dom,IF(Kalkulator!$C$10="","Polska",Kalkulator!$C$10),_xlpm.pocz,IF(Kalkulator!$K$5="",Kalkulator!$D$15,Kalkulator!$K$5),_xlpm.kon,IF(Kalkulator!$K$6="",Kalkulator!$D$20,Kalkulator!$K$6),_xlpm.puste,OR(_xlpm.n=0,_xlpm.i>_xlpm.n+1),_xlpm.prz,IF(Kalkulator!$I$15:$I$19="",Kalkulator!$D$15:$D$19,Kalkulator!$I$15:$I$19),_xlpm.wyj,IF(Kalkulator!$J$15:$J$19="",IF(Kalkulator!$C$16:$C$20<>"",Kalkulator!$D$16:$D$20,Kalkulator!$D$20),Kalkulator!$J$15:$J$19),IF(_xlpm.puste,"",IF(_xlpm.i=1,_xlpm.dom,INDEX(_xlpm.p,_xlpm.i-1))))} -> Poznań | C45: {=_xlfn.LET(_xlpm.n,COUNTIF(Kalkulator!$C$15:$C$19,"?*"),_xlpm.i,1,_xlpm.p,IF(Kalkulator!$H$15:$H$19<>"",Kalkulator!$H$15:$H$19,Kalkulator!$C$15:$C$19),_xlpm.dom,IF(Kalkulator!$C$10="","Polska",Kalkulator!$C$10),_xlpm.pocz,IF(Kalkulator!$K$5="",Kalkulator!$D$15,Kalkulator!$K$5),_xlpm.kon,IF(Kalkulator!$K$6="",Kalkulator!$D$20,Kalkulator!$K$6),_xlpm.puste,OR(_xlpm.n=0,_xlpm.i>_xlpm.n+1),_xlpm.prz,IF(Kalkulator!$I$15:$I$19="",Kalkulator!$D$15:$D$19,Kalkulator!$I$15:$I$19),_xlpm.wyj,IF(Kalkulator!$J$15:$J$19="",IF(Kalkulator!$C$16:$C$20<>"",Kalkulator!$D$16:$D$20,Kalkulator!$D$20),Kalkulator!$J$15:$J$19),_xlpm.v,IF(_xlpm.puste,0,N(IF(_xlpm.i=1,_xlpm.pocz,INDEX(_xlpm.wyj,_xlpm.i-1)))),IF(_xlpm.v=0,"",INT(_xlpm.v)))} -> 46279 | D45: {=_xlfn.LET(_xlpm.n,COUNTIF(Kalkulator!$C$15:$C$19,"?*"),_xlpm.i,1,_xlpm.p,IF(Kalkulator!$H$15:$H$19<>"",Kalkulator!$H$15:$H$19,Kalkulator!$C$15:$C$19),_xlpm.dom,IF(Kalkulator!$C$10="","Polska",Kalkulator!$C$10),_xlpm.pocz,IF(Kalkulator!$K$5="",Kalkulator!$D$15,Kalkulator!$K$5),_xlpm.kon,IF(Kalkulator!$K$6="",Kalkulator!$D$20,Kalkulator!$K$6),_xlpm.puste,OR(_xlpm.n=0,_xlpm.i>_xlpm.n+1),_xlpm.prz,IF(Kalkulator!$I$15:$I$19="",Kalkulator!$D$15:$D$19,Kalkulator!$I$15:$I$19),_xlpm.wyj,IF(Kalkulator!$J$15:$J$19="",IF(Kalkulator!$C$16:$C$20<>"",Kalkulator!$D$16:$D$20,Kalkulator!$D$20),Kalkulator!$J$15:$J$19),_xlpm.v,IF(_xlpm.puste,0,N(IF(_xlpm.i=1,_xlpm.pocz,INDEX(_xlpm.wyj,_xlpm.i-1)))),IF(_xlpm.v=0,"",MOD(_xlpm.v,1)))} -> 0.22916667 | E45: {=_xlfn.LET(_xlpm.n,COUNTIF(Kalkulator!$C$15:$C$19,"?*"),_xlpm.i,1,_xlpm.p,IF(Kalkulator!$H$15:$H$19<>"",Kalkulator!$H$15:$H$19,Kalkulator!$C$15:$C$19),_xlpm.dom,IF(Kalkulator!$C$10="","Polska",Kalkulator!$C$10),_xlpm.pocz,IF(Kalkulator!$K$5="",Kalkulator!$D$15,Kalkulator!$K$5),_xlpm.kon,IF(Kalkulator!$K$6="",Kalkulator!$D$20,Kalkulator!$K$6),_xlpm.puste,OR(_xlpm.n=0,_xlpm.i>_xlpm.n+1),_xlpm.prz,IF(Kalkulator!$I$15:$I$19="",Kalkulator!$D$15:$D$19,Kalkulator!$I$15:$I$19),_xlpm.wyj,IF(Kalkulator!$J$15:$J$19="",IF(Kalkulator!$C$16:$C$20<>"",Kalkulator!$D$16:$D$20,Kalkulator!$D$20),Kalkulator!$J$15:$J$19),IF(_xlpm.puste,"",IF(_xlpm.i<=_xlpm.n,INDEX(_xlpm.p,_xlpm.i),_xlpm.dom)))} -> Monachium | F45: {=_xlfn.LET(_xlpm.n,COUNTIF(Kalkulator!$C$15:$C$19,"?*"),_xlpm.i,1,_xlpm.p,IF(Kalkulator!$H$15:$H$19<>"",Kalkulator!$H$15:$H$19,Kalkulator!$C$15:$C$19),_xlpm.dom,IF(Kalkulator!$C$10="","Polska",Kalkulator!$C$10),_xlpm.pocz,IF(Kalkulator!$K$5="",Kalkulator!$D$15,Kalkulator!$K$5),_xlpm.kon,IF(Kalkulator!$K$6="",Kalkulator!$D$20,Kalkulator!$K$6),_xlpm.puste,OR(_xlpm.n=0,_xlpm.i>_xlpm.n+1),_xlpm.prz,IF(Kalkulator!$I$15:$I$19="",Kalkulator!$D$15:$D$19,Kalkulator!$I$15:$I$19),_xlpm.wyj,IF(Kalkulator!$J$15:$J$19="",IF(Kalkulator!$C$16:$C$20<>"",Kalkulator!$D$16:$D$20,Kalkulator!$D$20),Kalkulator!$J$15:$J$19),_xlpm.v,IF(_xlpm.puste,0,N(IF(_xlpm.i<=_xlpm.n,INDEX(_xlpm.prz,_xlpm.i),_xlpm.kon))),IF(_xlpm.v=0,"",INT(_xlpm.v)))} -> 46279 | G45: {=_xlfn.LET(_xlpm.n,COUNTIF(Kalkulator!$C$15:$C$19,"?*"),_xlpm.i,1,_xlpm.p,IF(Kalkulator!$H$15:$H$19<>"",Kalkulator!$H$15:$H$19,Kalkulator!$C$15:$C$19),_xlpm.dom,IF(Kalkulator!$C$10="","Polska",Kalkulator!$C$10),_xlpm.pocz,IF(Kalkulator!$K$5="",Kalkulator!$D$15,Kalkulator!$K$5),_xlpm.kon,IF(Kalkulator!$K$6="",Kalkulator!$D$20,Kalkulator!$K$6),_xlpm.puste,OR(_xlpm.n=0,_xlpm.i>_xlpm.n+1),_xlpm.prz,IF(Kalkulator!$I$15:$I$19="",Kalkulator!$D$15:$D$19,Kalkulator!$I$15:$I$19),_xlpm.wyj,IF(Kalkulator!$J$15:$J$19="",IF(Kalkulator!$C$16:$C$20<>"",Kalkulator!$D$16:$D$20,Kalkulator!$D$20),Kalkulator!$J$15:$J$19),_xlpm.v,IF(_xlpm.puste,0,N(IF(_xlpm.i<=_xlpm.n,INDEX(_xlpm.prz,_xlpm.i),_xlpm.kon))),IF(_xlpm.v=0,"",MOD(_xlpm.v,1)))} -> 0.51041667 | H45: {=_xlfn.LET(_xlpm.n,COUNTIF(Kalkulator!$C$15:$C$19,"?*"),_xlpm.i,1,_xlpm.p,IF(Kalkulator!$H$15:$H$19<>"",Kalkulator!$H$15:$H$19,Kalkulator!$C$15:$C$19),_xlpm.dom,IF(Kalkulator!$C$10="","Polska",Kalkulator!$C$10),_xlpm.pocz,IF(Kalkulator!$K$5="",Kalkulator!$D$15,Kalkulator!$K$5),_xlpm.kon,IF(Kalkulator!$K$6="",Kalkulator!$D$20,Kalkulator!$K$6),_xlpm.puste,OR(_xlpm.n=0,_xlpm.i>_xlpm.n+1),_xlpm.prz,IF(Kalkulator!$I$15:$I$19="",Kalkulator!$D$15:$D$19,Kalkulator!$I$15:$I$19),_xlpm.wyj,IF(Kalkulator!$J$15:$J$19="",IF(Kalkulator!$C$16:$C$20<>"",Kalkulator!$D$16:$D$20,Kalkulator!$D$20),Kalkulator!$J$15:$J$19),_xlpm.s,IF(_xlpm.puste,"",INDEX(Kalkulator!$K$15:$K$20,IF(_xlpm.i<=_xlpm.n,_xlpm.i,6))&""),IF(_xlpm.puste,"",IF(_xlpm.s="",Kalkulator!$C$11&"",_xlpm.s)))} -> samochód służbowy | I45: {=_xlfn.LET(_xlpm.n,COUNTIF(Kalkulator!$C$15:$C$19,"?*"),_xlpm.i,1,_xlpm.p,IF(Kalkulator!$H$15:$H$19<>"",Kalkulator!$H$15:$H$19,Kalkulator!$C$15:$C$19),_xlpm.dom,IF(Kalkulator!$C$10="","Polska",Kalkulator!$C$10),_xlpm.pocz,IF(Kalkulator!$K$5="",Kalkulator!$D$15,Kalkulator!$K$5),_xlpm.kon,IF(Kalkulator!$K$6="",Kalkulator!$D$20,Kalkulator!$K$6),_xlpm.puste,OR(_xlpm.n=0,_xlpm.i>_xlpm.n+1),_xlpm.prz,IF(Kalkulator!$I$15:$I$19="",Kalkulator!$D$15:$D$19,Kalkulator!$I$15:$I$19),_xlpm.wyj,IF(Kalkulator!$J$15:$J$19="",IF(Kalkulator!$C$16:$C$20<>"",Kalkulator!$D$16:$D$20,Kalkulator!$D$20),Kalkulator!$J$15:$J$19),IF(_xlpm.puste,"",INDEX(Kalkulator!$N$15:$N$20,IF(_xlpm.i<=_xlpm.n,_xlpm.i,6))))}
B46: {=_xlfn.LET(_xlpm.n,COUNTIF(Kalkulator!$C$15:$C$19,"?*"),_xlpm.i,2,_xlpm.p,IF(Kalkulator!$H$15:$H$19<>"",Kalkulator!$H$15:$H$19,Kalkulator!$C$15:$C$19),_xlpm.dom,IF(Kalkulator!$C$10="","Polska",Kalkulator!$C$10),_xlpm.pocz,IF(Kalkulator!$K$5="",Kalkulator!$D$15,Kalkulator!$K$5),_xlpm.kon,IF(Kalkulator!$K$6="",Kalkulator!$D$20,Kalkulator!$K$6),_xlpm.puste,OR(_xlpm.n=0,_xlpm.i>_xlpm.n+1),_xlpm.prz,IF(Kalkulator!$I$15:$I$19="",Kalkulator!$D$15:$D$19,Kalkulator!$I$15:$I$19),_xlpm.wyj,IF(Kalkulator!$J$15:$J$19="",IF(Kalkulator!$C$16:$C$20<>"",Kalkulator!$D$16:$D$20,Kalkulator!$D$20),Kalkulator!$J$15:$J$19),IF(_xlpm.puste,"",IF(_xlpm.i=1,_xlpm.dom,INDEX(_xlpm.p,_xlpm.i-1))))} -> Monachium | C46: {=_xlfn.LET(_xlpm.n,COUNTIF(Kalkulator!$C$15:$C$19,"?*"),_xlpm.i,2,_xlpm.p,IF(Kalkulator!$H$15:$H$19<>"",Kalkulator!$H$15:$H$19,Kalkulator!$C$15:$C$19),_xlpm.dom,IF(Kalkulator!$C$10="","Polska",Kalkulator!$C$10),_xlpm.pocz,IF(Kalkulator!$K$5="",Kalkulator!$D$15,Kalkulator!$K$5),_xlpm.kon,IF(Kalkulator!$K$6="",Kalkulator!$D$20,Kalkulator!$K$6),_xlpm.puste,OR(_xlpm.n=0,_xlpm.i>_xlpm.n+1),_xlpm.prz,IF(Kalkulator!$I$15:$I$19="",Kalkulator!$D$15:$D$19,Kalkulator!$I$15:$I$19),_xlpm.wyj,IF(Kalkulator!$J$15:$J$19="",IF(Kalkulator!$C$16:$C$20<>"",Kalkulator!$D$16:$D$20,Kalkulator!$D$20),Kalkulator!$J$15:$J$19),_xlpm.v,IF(_xlpm.puste,0,N(IF(_xlpm.i=1,_xlpm.pocz,INDEX(_xlpm.wyj,_xlpm.i-1)))),IF(_xlpm.v=0,"",INT(_xlpm.v)))} -> 46281 | D46: {=_xlfn.LET(_xlpm.n,COUNTIF(Kalkulator!$C$15:$C$19,"?*"),_xlpm.i,2,_xlpm.p,IF(Kalkulator!$H$15:$H$19<>"",Kalkulator!$H$15:$H$19,Kalkulator!$C$15:$C$19),_xlpm.dom,IF(Kalkulator!$C$10="","Polska",Kalkulator!$C$10),_xlpm.pocz,IF(Kalkulator!$K$5="",Kalkulator!$D$15,Kalkulator!$K$5),_xlpm.kon,IF(Kalkulator!$K$6="",Kalkulator!$D$20,Kalkulator!$K$6),_xlpm.puste,OR(_xlpm.n=0,_xlpm.i>_xlpm.n+1),_xlpm.prz,IF(Kalkulator!$I$15:$I$19="",Kalkulator!$D$15:$D$19,Kalkulator!$I$15:$I$19),_xlpm.wyj,IF(Kalkulator!$J$15:$J$19="",IF(Kalkulator!$C$16:$C$20<>"",Kalkulator!$D$16:$D$20,Kalkulator!$D$20),Kalkulator!$J$15:$J$19),_xlpm.v,IF(_xlpm.puste,0,N(IF(_xlpm.i=1,_xlpm.pocz,INDEX(_xlpm.wyj,_xlpm.i-1)))),IF(_xlpm.v=0,"",MOD(_xlpm.v,1)))} -> 0.375 | E46: {=_xlfn.LET(_xlpm.n,COUNTIF(Kalkulator!$C$15:$C$19,"?*"),_xlpm.i,2,_xlpm.p,IF(Kalkulator!$H$15:$H$19<>"",Kalkulator!$H$15:$H$19,Kalkulator!$C$15:$C$19),_xlpm.dom,IF(Kalkulator!$C$10="","Polska",Kalkulator!$C$10),_xlpm.pocz,IF(Kalkulator!$K$5="",Kalkulator!$D$15,Kalkulator!$K$5),_xlpm.kon,IF(Kalkulator!$K$6="",Kalkulator!$D$20,Kalkulator!$K$6),_xlpm.puste,OR(_xlpm.n=0,_xlpm.i>_xlpm.n+1),_xlpm.prz,IF(Kalkulator!$I$15:$I$19="",Kalkulator!$D$15:$D$19,Kalkulator!$I$15:$I$19),_xlpm.wyj,IF(Kalkulator!$J$15:$J$19="",IF(Kalkulator!$C$16:$C$20<>"",Kalkulator!$D$16:$D$20,Kalkulator!$D$20),Kalkulator!$J$15:$J$19),IF(_xlpm.puste,"",IF(_xlpm.i<=_xlpm.n,INDEX(_xlpm.p,_xlpm.i),_xlpm.dom)))} -> Linz | F46: {=_xlfn.LET(_xlpm.n,COUNTIF(Kalkulator!$C$15:$C$19,"?*"),_xlpm.i,2,_xlpm.p,IF(Kalkulator!$H$15:$H$19<>"",Kalkulator!$H$15:$H$19,Kalkulator!$C$15:$C$19),_xlpm.dom,IF(Kalkulator!$C$10="","Polska",Kalkulator!$C$10),_xlpm.pocz,IF(Kalkulator!$K$5="",Kalkulator!$D$15,Kalkulator!$K$5),_xlpm.kon,IF(Kalkulator!$K$6="",Kalkulator!$D$20,Kalkulator!$K$6),_xlpm.puste,OR(_xlpm.n=0,_xlpm.i>_xlpm.n+1),_xlpm.prz,IF(Kalkulator!$I$15:$I$19="",Kalkulator!$D$15:$D$19,Kalkulator!$I$15:$I$19),_xlpm.wyj,IF(Kalkulator!$J$15:$J$19="",IF(Kalkulator!$C$16:$C$20<>"",Kalkulator!$D$16:$D$20,Kalkulator!$D$20),Kalkulator!$J$15:$J$19),_xlpm.v,IF(_xlpm.puste,0,N(IF(_xlpm.i<=_xlpm.n,INDEX(_xlpm.prz,_xlpm.i),_xlpm.kon))),IF(_xlpm.v=0,"",INT(_xlpm.v)))} -> 46281 | G46: {=_xlfn.LET(_xlpm.n,COUNTIF(Kalkulator!$C$15:$C$19,"?*"),_xlpm.i,2,_xlpm.p,IF(Kalkulator!$H$15:$H$19<>"",Kalkulator!$H$15:$H$19,Kalkulator!$C$15:$C$19),_xlpm.dom,IF(Kalkulator!$C$10="","Polska",Kalkulator!$C$10),_xlpm.pocz,IF(Kalkulator!$K$5="",Kalkulator!$D$15,Kalkulator!$K$5),_xlpm.kon,IF(Kalkulator!$K$6="",Kalkulator!$D$20,Kalkulator!$K$6),_xlpm.puste,OR(_xlpm.n=0,_xlpm.i>_xlpm.n+1),_xlpm.prz,IF(Kalkulator!$I$15:$I$19="",Kalkulator!$D$15:$D$19,Kalkulator!$I$15:$I$19),_xlpm.wyj,IF(Kalkulator!$J$15:$J$19="",IF(Kalkulator!$C$16:$C$20<>"",Kalkulator!$D$16:$D$20,Kalkulator!$D$20),Kalkulator!$J$15:$J$19),_xlpm.v,IF(_xlpm.puste,0,N(IF(_xlpm.i<=_xlpm.n,INDEX(_xlpm.prz,_xlpm.i),_xlpm.kon))),IF(_xlpm.v=0,"",MOD(_xlpm.v,1)))} -> 0.64583333 | H46: {=_xlfn.LET(_xlpm.n,COUNTIF(Kalkulator!$C$15:$C$19,"?*"),_xlpm.i,2,_xlpm.p,IF(Kalkulator!$H$15:$H$19<>"",Kalkulator!$H$15:$H$19,Kalkulator!$C$15:$C$19),_xlpm.dom,IF(Kalkulator!$C$10="","Polska",Kalkulator!$C$10),_xlpm.pocz,IF(Kalkulator!$K$5="",Kalkulator!$D$15,Kalkulator!$K$5),_xlpm.kon,IF(Kalkulator!$K$6="",Kalkulator!$D$20,Kalkulator!$K$6),_xlpm.puste,OR(_xlpm.n=0,_xlpm.i>_xlpm.n+1),_xlpm.prz,IF(Kalkulator!$I$15:$I$19="",Kalkulator!$D$15:$D$19,Kalkulator!$I$15:$I$19),_xlpm.wyj,IF(Kalkulator!$J$15:$J$19="",IF(Kalkulator!$C$16:$C$20<>"",Kalkulator!$D$16:$D$20,Kalkulator!$D$20),Kalkulator!$J$15:$J$19),_xlpm.s,IF(_xlpm.puste,"",INDEX(Kalkulator!$K$15:$K$20,IF(_xlpm.i<=_xlpm.n,_xlpm.i,6))&""),IF(_xlpm.puste,"",IF(_xlpm.s="",Kalkulator!$C$11&"",_xlpm.s)))} -> samochód służbowy | I46: {=_xlfn.LET(_xlpm.n,COUNTIF(Kalkulator!$C$15:$C$19,"?*"),_xlpm.i,2,_xlpm.p,IF(Kalkulator!$H$15:$H$19<>"",Kalkulator!$H$15:$H$19,Kalkulator!$C$15:$C$19),_xlpm.dom,IF(Kalkulator!$C$10="","Polska",Kalkulator!$C$10),_xlpm.pocz,IF(Kalkulator!$K$5="",Kalkulator!$D$15,Kalkulator!$K$5),_xlpm.kon,IF(Kalkulator!$K$6="",Kalkulator!$D$20,Kalkulator!$K$6),_xlpm.puste,OR(_xlpm.n=0,_xlpm.i>_xlpm.n+1),_xlpm.prz,IF(Kalkulator!$I$15:$I$19="",Kalkulator!$D$15:$D$19,Kalkulator!$I$15:$I$19),_xlpm.wyj,IF(Kalkulator!$J$15:$J$19="",IF(Kalkulator!$C$16:$C$20<>"",Kalkulator!$D$16:$D$20,Kalkulator!$D$20),Kalkulator!$J$15:$J$19),IF(_xlpm.puste,"",INDEX(Kalkulator!$N$15:$N$20,IF(_xlpm.i<=_xlpm.n,_xlpm.i,6))))}
B47: {=_xlfn.LET(_xlpm.n,COUNTIF(Kalkulator!$C$15:$C$19,"?*"),_xlpm.i,3,_xlpm.p,IF(Kalkulator!$H$15:$H$19<>"",Kalkulator!$H$15:$H$19,Kalkulator!$C$15:$C$19),_xlpm.dom,IF(Kalkulator!$C$10="","Polska",Kalkulator!$C$10),_xlpm.pocz,IF(Kalkulator!$K$5="",Kalkulator!$D$15,Kalkulator!$K$5),_xlpm.kon,IF(Kalkulator!$K$6="",Kalkulator!$D$20,Kalkulator!$K$6),_xlpm.puste,OR(_xlpm.n=0,_xlpm.i>_xlpm.n+1),_xlpm.prz,IF(Kalkulator!$I$15:$I$19="",Kalkulator!$D$15:$D$19,Kalkulator!$I$15:$I$19),_xlpm.wyj,IF(Kalkulator!$J$15:$J$19="",IF(Kalkulator!$C$16:$C$20<>"",Kalkulator!$D$16:$D$20,Kalkulator!$D$20),Kalkulator!$J$15:$J$19),IF(_xlpm.puste,"",IF(_xlpm.i=1,_xlpm.dom,INDEX(_xlpm.p,_xlpm.i-1))))} -> Linz | C47: {=_xlfn.LET(_xlpm.n,COUNTIF(Kalkulator!$C$15:$C$19,"?*"),_xlpm.i,3,_xlpm.p,IF(Kalkulator!$H$15:$H$19<>"",Kalkulator!$H$15:$H$19,Kalkulator!$C$15:$C$19),_xlpm.dom,IF(Kalkulator!$C$10="","Polska",Kalkulator!$C$10),_xlpm.pocz,IF(Kalkulator!$K$5="",Kalkulator!$D$15,Kalkulator!$K$5),_xlpm.kon,IF(Kalkulator!$K$6="",Kalkulator!$D$20,Kalkulator!$K$6),_xlpm.puste,OR(_xlpm.n=0,_xlpm.i>_xlpm.n+1),_xlpm.prz,IF(Kalkulator!$I$15:$I$19="",Kalkulator!$D$15:$D$19,Kalkulator!$I$15:$I$19),_xlpm.wyj,IF(Kalkulator!$J$15:$J$19="",IF(Kalkulator!$C$16:$C$20<>"",Kalkulator!$D$16:$D$20,Kalkulator!$D$20),Kalkulator!$J$15:$J$19),_xlpm.v,IF(_xlpm.puste,0,N(IF(_xlpm.i=1,_xlpm.pocz,INDEX(_xlpm.wyj,_xlpm.i-1)))),IF(_xlpm.v=0,"",INT(_xlpm.v)))} -> 46283 | D47: {=_xlfn.LET(_xlpm.n,COUNTIF(Kalkulator!$C$15:$C$19,"?*"),_xlpm.i,3,_xlpm.p,IF(Kalkulator!$H$15:$H$19<>"",Kalkulator!$H$15:$H$19,Kalkulator!$C$15:$C$19),_xlpm.dom,IF(Kalkulator!$C$10="","Polska",Kalkulator!$C$10),_xlpm.pocz,IF(Kalkulator!$K$5="",Kalkulator!$D$15,Kalkulator!$K$5),_xlpm.kon,IF(Kalkulator!$K$6="",Kalkulator!$D$20,Kalkulator!$K$6),_xlpm.puste,OR(_xlpm.n=0,_xlpm.i>_xlpm.n+1),_xlpm.prz,IF(Kalkulator!$I$15:$I$19="",Kalkulator!$D$15:$D$19,Kalkulator!$I$15:$I$19),_xlpm.wyj,IF(Kalkulator!$J$15:$J$19="",IF(Kalkulator!$C$16:$C$20<>"",Kalkulator!$D$16:$D$20,Kalkulator!$D$20),Kalkulator!$J$15:$J$19),_xlpm.v,IF(_xlpm.puste,0,N(IF(_xlpm.i=1,_xlpm.pocz,INDEX(_xlpm.wyj,_xlpm.i-1)))),IF(_xlpm.v=0,"",MOD(_xlpm.v,1)))} -> 0.58333333 | E47: {=_xlfn.LET(_xlpm.n,COUNTIF(Kalkulator!$C$15:$C$19,"?*"),_xlpm.i,3,_xlpm.p,IF(Kalkulator!$H$15:$H$19<>"",Kalkulator!$H$15:$H$19,Kalkulator!$C$15:$C$19),_xlpm.dom,IF(Kalkulator!$C$10="","Polska",Kalkulator!$C$10),_xlpm.pocz,IF(Kalkulator!$K$5="",Kalkulator!$D$15,Kalkulator!$K$5),_xlpm.kon,IF(Kalkulator!$K$6="",Kalkulator!$D$20,Kalkulator!$K$6),_xlpm.puste,OR(_xlpm.n=0,_xlpm.i>_xlpm.n+1),_xlpm.prz,IF(Kalkulator!$I$15:$I$19="",Kalkulator!$D$15:$D$19,Kalkulator!$I$15:$I$19),_xlpm.wyj,IF(Kalkulator!$J$15:$J$19="",IF(Kalkulator!$C$16:$C$20<>"",Kalkulator!$D$16:$D$20,Kalkulator!$D$20),Kalkulator!$J$15:$J$19),IF(_xlpm.puste,"",IF(_xlpm.i<=_xlpm.n,INDEX(_xlpm.p,_xlpm.i),_xlpm.dom)))} -> Poznań | F47: {=_xlfn.LET(_xlpm.n,COUNTIF(Kalkulator!$C$15:$C$19,"?*"),_xlpm.i,3,_xlpm.p,IF(Kalkulator!$H$15:$H$19<>"",Kalkulator!$H$15:$H$19,Kalkulator!$C$15:$C$19),_xlpm.dom,IF(Kalkulator!$C$10="","Polska",Kalkulator!$C$10),_xlpm.pocz,IF(Kalkulator!$K$5="",Kalkulator!$D$15,Kalkulator!$K$5),_xlpm.kon,IF(Kalkulator!$K$6="",Kalkulator!$D$20,Kalkulator!$K$6),_xlpm.puste,OR(_xlpm.n=0,_xlpm.i>_xlpm.n+1),_xlpm.prz,IF(Kalkulator!$I$15:$I$19="",Kalkulator!$D$15:$D$19,Kalkulator!$I$15:$I$19),_xlpm.wyj,IF(Kalkulator!$J$15:$J$19="",IF(Kalkulator!$C$16:$C$20<>"",Kalkulator!$D$16:$D$20,Kalkulator!$D$20),Kalkulator!$J$15:$J$19),_xlpm.v,IF(_xlpm.puste,0,N(IF(_xlpm.i<=_xlpm.n,INDEX(_xlpm.prz,_xlpm.i),_xlpm.kon))),IF(_xlpm.v=0,"",INT(_xlpm.v)))} -> 46283 | G47: {=_xlfn.LET(_xlpm.n,COUNTIF(Kalkulator!$C$15:$C$19,"?*"),_xlpm.i,3,_xlpm.p,IF(Kalkulator!$H$15:$H$19<>"",Kalkulator!$H$15:$H$19,Kalkulator!$C$15:$C$19),_xlpm.dom,IF(Kalkulator!$C$10="","Polska",Kalkulator!$C$10),_xlpm.pocz,IF(Kalkulator!$K$5="",Kalkulator!$D$15,Kalkulator!$K$5),_xlpm.kon,IF(Kalkulator!$K$6="",Kalkulator!$D$20,Kalkulator!$K$6),_xlpm.puste,OR(_xlpm.n=0,_xlpm.i>_xlpm.n+1),_xlpm.prz,IF(Kalkulator!$I$15:$I$19="",Kalkulator!$D$15:$D$19,Kalkulator!$I$15:$I$19),_xlpm.wyj,IF(Kalkulator!$J$15:$J$19="",IF(Kalkulator!$C$16:$C$20<>"",Kalkulator!$D$16:$D$20,Kalkulator!$D$20),Kalkulator!$J$15:$J$19),_xlpm.v,IF(_xlpm.puste,0,N(IF(_xlpm.i<=_xlpm.n,INDEX(_xlpm.prz,_xlpm.i),_xlpm.kon))),IF(_xlpm.v=0,"",MOD(_xlpm.v,1)))} -> 0.91666667 | H47: {=_xlfn.LET(_xlpm.n,COUNTIF(Kalkulator!$C$15:$C$19,"?*"),_xlpm.i,3,_xlpm.p,IF(Kalkulator!$H$15:$H$19<>"",Kalkulator!$H$15:$H$19,Kalkulator!$C$15:$C$19),_xlpm.dom,IF(Kalkulator!$C$10="","Polska",Kalkulator!$C$10),_xlpm.pocz,IF(Kalkulator!$K$5="",Kalkulator!$D$15,Kalkulator!$K$5),_xlpm.kon,IF(Kalkulator!$K$6="",Kalkulator!$D$20,Kalkulator!$K$6),_xlpm.puste,OR(_xlpm.n=0,_xlpm.i>_xlpm.n+1),_xlpm.prz,IF(Kalkulator!$I$15:$I$19="",Kalkulator!$D$15:$D$19,Kalkulator!$I$15:$I$19),_xlpm.wyj,IF(Kalkulator!$J$15:$J$19="",IF(Kalkulator!$C$16:$C$20<>"",Kalkulator!$D$16:$D$20,Kalkulator!$D$20),Kalkulator!$J$15:$J$19),_xlpm.s,IF(_xlpm.puste,"",INDEX(Kalkulator!$K$15:$K$20,IF(_xlpm.i<=_xlpm.n,_xlpm.i,6))&""),IF(_xlpm.puste,"",IF(_xlpm.s="",Kalkulator!$C$11&"",_xlpm.s)))} -> samochód służbowy | I47: {=_xlfn.LET(_xlpm.n,COUNTIF(Kalkulator!$C$15:$C$19,"?*"),_xlpm.i,3,_xlpm.p,IF(Kalkulator!$H$15:$H$19<>"",Kalkulator!$H$15:$H$19,Kalkulator!$C$15:$C$19),_xlpm.dom,IF(Kalkulator!$C$10="","Polska",Kalkulator!$C$10),_xlpm.pocz,IF(Kalkulator!$K$5="",Kalkulator!$D$15,Kalkulator!$K$5),_xlpm.kon,IF(Kalkulator!$K$6="",Kalkulator!$D$20,Kalkulator!$K$6),_xlpm.puste,OR(_xlpm.n=0,_xlpm.i>_xlpm.n+1),_xlpm.prz,IF(Kalkulator!$I$15:$I$19="",Kalkulator!$D$15:$D$19,Kalkulator!$I$15:$I$19),_xlpm.wyj,IF(Kalkulator!$J$15:$J$19="",IF(Kalkulator!$C$16:$C$20<>"",Kalkulator!$D$16:$D$20,Kalkulator!$D$20),Kalkulator!$J$15:$J$19),IF(_xlpm.puste,"",INDEX(Kalkulator!$N$15:$N$20,IF(_xlpm.i<=_xlpm.n,_xlpm.i,6))))}
B48: {=_xlfn.LET(_xlpm.n,COUNTIF(Kalkulator!$C$15:$C$19,"?*"),_xlpm.i,4,_xlpm.p,IF(Kalkulator!$H$15:$H$19<>"",Kalkulator!$H$15:$H$19,Kalkulator!$C$15:$C$19),_xlpm.dom,IF(Kalkulator!$C$10="","Polska",Kalkulator!$C$10),_xlpm.pocz,IF(Kalkulator!$K$5="",Kalkulator!$D$15,Kalkulator!$K$5),_xlpm.kon,IF(Kalkulator!$K$6="",Kalkulator!$D$20,Kalkulator!$K$6),_xlpm.puste,OR(_xlpm.n=0,_xlpm.i>_xlpm.n+1),_xlpm.prz,IF(Kalkulator!$I$15:$I$19="",Kalkulator!$D$15:$D$19,Kalkulator!$I$15:$I$19),_xlpm.wyj,IF(Kalkulator!$J$15:$J$19="",IF(Kalkulator!$C$16:$C$20<>"",Kalkulator!$D$16:$D$20,Kalkulator!$D$20),Kalkulator!$J$15:$J$19),IF(_xlpm.puste,"",IF(_xlpm.i=1,_xlpm.dom,INDEX(_xlpm.p,_xlpm.i-1))))} | C48: {=_xlfn.LET(_xlpm.n,COUNTIF(Kalkulator!$C$15:$C$19,"?*"),_xlpm.i,4,_xlpm.p,IF(Kalkulator!$H$15:$H$19<>"",Kalkulator!$H$15:$H$19,Kalkulator!$C$15:$C$19),_xlpm.dom,IF(Kalkulator!$C$10="","Polska",Kalkulator!$C$10),_xlpm.pocz,IF(Kalkulator!$K$5="",Kalkulator!$D$15,Kalkulator!$K$5),_xlpm.kon,IF(Kalkulator!$K$6="",Kalkulator!$D$20,Kalkulator!$K$6),_xlpm.puste,OR(_xlpm.n=0,_xlpm.i>_xlpm.n+1),_xlpm.prz,IF(Kalkulator!$I$15:$I$19="",Kalkulator!$D$15:$D$19,Kalkulator!$I$15:$I$19),_xlpm.wyj,IF(Kalkulator!$J$15:$J$19="",IF(Kalkulator!$C$16:$C$20<>"",Kalkulator!$D$16:$D$20,Kalkulator!$D$20),Kalkulator!$J$15:$J$19),_xlpm.v,IF(_xlpm.puste,0,N(IF(_xlpm.i=1,_xlpm.pocz,INDEX(_xlpm.wyj,_xlpm.i-1)))),IF(_xlpm.v=0,"",INT(_xlpm.v)))} | D48: {=_xlfn.LET(_xlpm.n,COUNTIF(Kalkulator!$C$15:$C$19,"?*"),_xlpm.i,4,_xlpm.p,IF(Kalkulator!$H$15:$H$19<>"",Kalkulator!$H$15:$H$19,Kalkulator!$C$15:$C$19),_xlpm.dom,IF(Kalkulator!$C$10="","Polska",Kalkulator!$C$10),_xlpm.pocz,IF(Kalkulator!$K$5="",Kalkulator!$D$15,Kalkulator!$K$5),_xlpm.kon,IF(Kalkulator!$K$6="",Kalkulator!$D$20,Kalkulator!$K$6),_xlpm.puste,OR(_xlpm.n=0,_xlpm.i>_xlpm.n+1),_xlpm.prz,IF(Kalkulator!$I$15:$I$19="",Kalkulator!$D$15:$D$19,Kalkulator!$I$15:$I$19),_xlpm.wyj,IF(Kalkulator!$J$15:$J$19="",IF(Kalkulator!$C$16:$C$20<>"",Kalkulator!$D$16:$D$20,Kalkulator!$D$20),Kalkulator!$J$15:$J$19),_xlpm.v,IF(_xlpm.puste,0,N(IF(_xlpm.i=1,_xlpm.pocz,INDEX(_xlpm.wyj,_xlpm.i-1)))),IF(_xlpm.v=0,"",MOD(_xlpm.v,1)))} | E48: {=_xlfn.LET(_xlpm.n,COUNTIF(Kalkulator!$C$15:$C$19,"?*"),_xlpm.i,4,_xlpm.p,IF(Kalkulator!$H$15:$H$19<>"",Kalkulator!$H$15:$H$19,Kalkulator!$C$15:$C$19),_xlpm.dom,IF(Kalkulator!$C$10="","Polska",Kalkulator!$C$10),_xlpm.pocz,IF(Kalkulator!$K$5="",Kalkulator!$D$15,Kalkulator!$K$5),_xlpm.kon,IF(Kalkulator!$K$6="",Kalkulator!$D$20,Kalkulator!$K$6),_xlpm.puste,OR(_xlpm.n=0,_xlpm.i>_xlpm.n+1),_xlpm.prz,IF(Kalkulator!$I$15:$I$19="",Kalkulator!$D$15:$D$19,Kalkulator!$I$15:$I$19),_xlpm.wyj,IF(Kalkulator!$J$15:$J$19="",IF(Kalkulator!$C$16:$C$20<>"",Kalkulator!$D$16:$D$20,Kalkulator!$D$20),Kalkulator!$J$15:$J$19),IF(_xlpm.puste,"",IF(_xlpm.i<=_xlpm.n,INDEX(_xlpm.p,_xlpm.i),_xlpm.dom)))} | F48: {=_xlfn.LET(_xlpm.n,COUNTIF(Kalkulator!$C$15:$C$19,"?*"),_xlpm.i,4,_xlpm.p,IF(Kalkulator!$H$15:$H$19<>"",Kalkulator!$H$15:$H$19,Kalkulator!$C$15:$C$19),_xlpm.dom,IF(Kalkulator!$C$10="","Polska",Kalkulator!$C$10),_xlpm.pocz,IF(Kalkulator!$K$5="",Kalkulator!$D$15,Kalkulator!$K$5),_xlpm.kon,IF(Kalkulator!$K$6="",Kalkulator!$D$20,Kalkulator!$K$6),_xlpm.puste,OR(_xlpm.n=0,_xlpm.i>_xlpm.n+1),_xlpm.prz,IF(Kalkulator!$I$15:$I$19="",Kalkulator!$D$15:$D$19,Kalkulator!$I$15:$I$19),_xlpm.wyj,IF(Kalkulator!$J$15:$J$19="",IF(Kalkulator!$C$16:$C$20<>"",Kalkulator!$D$16:$D$20,Kalkulator!$D$20),Kalkulator!$J$15:$J$19),_xlpm.v,IF(_xlpm.puste,0,N(IF(_xlpm.i<=_xlpm.n,INDEX(_xlpm.prz,_xlpm.i),_xlpm.kon))),IF(_xlpm.v=0,"",INT(_xlpm.v)))} | G48: {=_xlfn.LET(_xlpm.n,COUNTIF(Kalkulator!$C$15:$C$19,"?*"),_xlpm.i,4,_xlpm.p,IF(Kalkulator!$H$15:$H$19<>"",Kalkulator!$H$15:$H$19,Kalkulator!$C$15:$C$19),_xlpm.dom,IF(Kalkulator!$C$10="","Polska",Kalkulator!$C$10),_xlpm.pocz,IF(Kalkulator!$K$5="",Kalkulator!$D$15,Kalkulator!$K$5),_xlpm.kon,IF(Kalkulator!$K$6="",Kalkulator!$D$20,Kalkulator!$K$6),_xlpm.puste,OR(_xlpm.n=0,_xlpm.i>_xlpm.n+1),_xlpm.prz,IF(Kalkulator!$I$15:$I$19="",Kalkulator!$D$15:$D$19,Kalkulator!$I$15:$I$19),_xlpm.wyj,IF(Kalkulator!$J$15:$J$19="",IF(Kalkulator!$C$16:$C$20<>"",Kalkulator!$D$16:$D$20,Kalkulator!$D$20),Kalkulator!$J$15:$J$19),_xlpm.v,IF(_xlpm.puste,0,N(IF(_xlpm.i<=_xlpm.n,INDEX(_xlpm.prz,_xlpm.i),_xlpm.kon))),IF(_xlpm.v=0,"",MOD(_xlpm.v,1)))} | H48: {=_xlfn.LET(_xlpm.n,COUNTIF(Kalkulator!$C$15:$C$19,"?*"),_xlpm.i,4,_xlpm.p,IF(Kalkulator!$H$15:$H$19<>"",Kalkulator!$H$15:$H$19,Kalkulator!$C$15:$C$19),_xlpm.dom,IF(Kalkulator!$C$10="","Polska",Kalkulator!$C$10),_xlpm.pocz,IF(Kalkulator!$K$5="",Kalkulator!$D$15,Kalkulator!$K$5),_xlpm.kon,IF(Kalkulator!$K$6="",Kalkulator!$D$20,Kalkulator!$K$6),_xlpm.puste,OR(_xlpm.n=0,_xlpm.i>_xlpm.n+1),_xlpm.prz,IF(Kalkulator!$I$15:$I$19="",Kalkulator!$D$15:$D$19,Kalkulator!$I$15:$I$19),_xlpm.wyj,IF(Kalkulator!$J$15:$J$19="",IF(Kalkulator!$C$16:$C$20<>"",Kalkulator!$D$16:$D$20,Kalkulator!$D$20),Kalkulator!$J$15:$J$19),_xlpm.s,IF(_xlpm.puste,"",INDEX(Kalkulator!$K$15:$K$20,IF(_xlpm.i<=_xlpm.n,_xlpm.i,6))&""),IF(_xlpm.puste,"",IF(_xlpm.s="",Kalkulator!$C$11&"",_xlpm.s)))} | I48: {=_xlfn.LET(_xlpm.n,COUNTIF(Kalkulator!$C$15:$C$19,"?*"),_xlpm.i,4,_xlpm.p,IF(Kalkulator!$H$15:$H$19<>"",Kalkulator!$H$15:$H$19,Kalkulator!$C$15:$C$19),_xlpm.dom,IF(Kalkulator!$C$10="","Polska",Kalkulator!$C$10),_xlpm.pocz,IF(Kalkulator!$K$5="",Kalkulator!$D$15,Kalkulator!$K$5),_xlpm.kon,IF(Kalkulator!$K$6="",Kalkulator!$D$20,Kalkulator!$K$6),_xlpm.puste,OR(_xlpm.n=0,_xlpm.i>_xlpm.n+1),_xlpm.prz,IF(Kalkulator!$I$15:$I$19="",Kalkulator!$D$15:$D$19,Kalkulator!$I$15:$I$19),_xlpm.wyj,IF(Kalkulator!$J$15:$J$19="",IF(Kalkulator!$C$16:$C$20<>"",Kalkulator!$D$16:$D$20,Kalkulator!$D$20),Kalkulator!$J$15:$J$19),IF(_xlpm.puste,"",INDEX(Kalkulator!$N$15:$N$20,IF(_xlpm.i<=_xlpm.n,_xlpm.i,6))))}
B49: {=_xlfn.LET(_xlpm.n,COUNTIF(Kalkulator!$C$15:$C$19,"?*"),_xlpm.i,5,_xlpm.p,IF(Kalkulator!$H$15:$H$19<>"",Kalkulator!$H$15:$H$19,Kalkulator!$C$15:$C$19),_xlpm.dom,IF(Kalkulator!$C$10="","Polska",Kalkulator!$C$10),_xlpm.pocz,IF(Kalkulator!$K$5="",Kalkulator!$D$15,Kalkulator!$K$5),_xlpm.kon,IF(Kalkulator!$K$6="",Kalkulator!$D$20,Kalkulator!$K$6),_xlpm.puste,OR(_xlpm.n=0,_xlpm.i>_xlpm.n+1),_xlpm.prz,IF(Kalkulator!$I$15:$I$19="",Kalkulator!$D$15:$D$19,Kalkulator!$I$15:$I$19),_xlpm.wyj,IF(Kalkulator!$J$15:$J$19="",IF(Kalkulator!$C$16:$C$20<>"",Kalkulator!$D$16:$D$20,Kalkulator!$D$20),Kalkulator!$J$15:$J$19),IF(_xlpm.puste,"",IF(_xlpm.i=1,_xlpm.dom,INDEX(_xlpm.p,_xlpm.i-1))))} | C49: {=_xlfn.LET(_xlpm.n,COUNTIF(Kalkulator!$C$15:$C$19,"?*"),_xlpm.i,5,_xlpm.p,IF(Kalkulator!$H$15:$H$19<>"",Kalkulator!$H$15:$H$19,Kalkulator!$C$15:$C$19),_xlpm.dom,IF(Kalkulator!$C$10="","Polska",Kalkulator!$C$10),_xlpm.pocz,IF(Kalkulator!$K$5="",Kalkulator!$D$15,Kalkulator!$K$5),_xlpm.kon,IF(Kalkulator!$K$6="",Kalkulator!$D$20,Kalkulator!$K$6),_xlpm.puste,OR(_xlpm.n=0,_xlpm.i>_xlpm.n+1),_xlpm.prz,IF(Kalkulator!$I$15:$I$19="",Kalkulator!$D$15:$D$19,Kalkulator!$I$15:$I$19),_xlpm.wyj,IF(Kalkulator!$J$15:$J$19="",IF(Kalkulator!$C$16:$C$20<>"",Kalkulator!$D$16:$D$20,Kalkulator!$D$20),Kalkulator!$J$15:$J$19),_xlpm.v,IF(_xlpm.puste,0,N(IF(_xlpm.i=1,_xlpm.pocz,INDEX(_xlpm.wyj,_xlpm.i-1)))),IF(_xlpm.v=0,"",INT(_xlpm.v)))} | D49: {=_xlfn.LET(_xlpm.n,COUNTIF(Kalkulator!$C$15:$C$19,"?*"),_xlpm.i,5,_xlpm.p,IF(Kalkulator!$H$15:$H$19<>"",Kalkulator!$H$15:$H$19,Kalkulator!$C$15:$C$19),_xlpm.dom,IF(Kalkulator!$C$10="","Polska",Kalkulator!$C$10),_xlpm.pocz,IF(Kalkulator!$K$5="",Kalkulator!$D$15,Kalkulator!$K$5),_xlpm.kon,IF(Kalkulator!$K$6="",Kalkulator!$D$20,Kalkulator!$K$6),_xlpm.puste,OR(_xlpm.n=0,_xlpm.i>_xlpm.n+1),_xlpm.prz,IF(Kalkulator!$I$15:$I$19="",Kalkulator!$D$15:$D$19,Kalkulator!$I$15:$I$19),_xlpm.wyj,IF(Kalkulator!$J$15:$J$19="",IF(Kalkulator!$C$16:$C$20<>"",Kalkulator!$D$16:$D$20,Kalkulator!$D$20),Kalkulator!$J$15:$J$19),_xlpm.v,IF(_xlpm.puste,0,N(IF(_xlpm.i=1,_xlpm.pocz,INDEX(_xlpm.wyj,_xlpm.i-1)))),IF(_xlpm.v=0,"",MOD(_xlpm.v,1)))} | E49: {=_xlfn.LET(_xlpm.n,COUNTIF(Kalkulator!$C$15:$C$19,"?*"),_xlpm.i,5,_xlpm.p,IF(Kalkulator!$H$15:$H$19<>"",Kalkulator!$H$15:$H$19,Kalkulator!$C$15:$C$19),_xlpm.dom,IF(Kalkulator!$C$10="","Polska",Kalkulator!$C$10),_xlpm.pocz,IF(Kalkulator!$K$5="",Kalkulator!$D$15,Kalkulator!$K$5),_xlpm.kon,IF(Kalkulator!$K$6="",Kalkulator!$D$20,Kalkulator!$K$6),_xlpm.puste,OR(_xlpm.n=0,_xlpm.i>_xlpm.n+1),_xlpm.prz,IF(Kalkulator!$I$15:$I$19="",Kalkulator!$D$15:$D$19,Kalkulator!$I$15:$I$19),_xlpm.wyj,IF(Kalkulator!$J$15:$J$19="",IF(Kalkulator!$C$16:$C$20<>"",Kalkulator!$D$16:$D$20,Kalkulator!$D$20),Kalkulator!$J$15:$J$19),IF(_xlpm.puste,"",IF(_xlpm.i<=_xlpm.n,INDEX(_xlpm.p,_xlpm.i),_xlpm.dom)))} | F49: {=_xlfn.LET(_xlpm.n,COUNTIF(Kalkulator!$C$15:$C$19,"?*"),_xlpm.i,5,_xlpm.p,IF(Kalkulator!$H$15:$H$19<>"",Kalkulator!$H$15:$H$19,Kalkulator!$C$15:$C$19),_xlpm.dom,IF(Kalkulator!$C$10="","Polska",Kalkulator!$C$10),_xlpm.pocz,IF(Kalkulator!$K$5="",Kalkulator!$D$15,Kalkulator!$K$5),_xlpm.kon,IF(Kalkulator!$K$6="",Kalkulator!$D$20,Kalkulator!$K$6),_xlpm.puste,OR(_xlpm.n=0,_xlpm.i>_xlpm.n+1),_xlpm.prz,IF(Kalkulator!$I$15:$I$19="",Kalkulator!$D$15:$D$19,Kalkulator!$I$15:$I$19),_xlpm.wyj,IF(Kalkulator!$J$15:$J$19="",IF(Kalkulator!$C$16:$C$20<>"",Kalkulator!$D$16:$D$20,Kalkulator!$D$20),Kalkulator!$J$15:$J$19),_xlpm.v,IF(_xlpm.puste,0,N(IF(_xlpm.i<=_xlpm.n,INDEX(_xlpm.prz,_xlpm.i),_xlpm.kon))),IF(_xlpm.v=0,"",INT(_xlpm.v)))} | G49: {=_xlfn.LET(_xlpm.n,COUNTIF(Kalkulator!$C$15:$C$19,"?*"),_xlpm.i,5,_xlpm.p,IF(Kalkulator!$H$15:$H$19<>"",Kalkulator!$H$15:$H$19,Kalkulator!$C$15:$C$19),_xlpm.dom,IF(Kalkulator!$C$10="","Polska",Kalkulator!$C$10),_xlpm.pocz,IF(Kalkulator!$K$5="",Kalkulator!$D$15,Kalkulator!$K$5),_xlpm.kon,IF(Kalkulator!$K$6="",Kalkulator!$D$20,Kalkulator!$K$6),_xlpm.puste,OR(_xlpm.n=0,_xlpm.i>_xlpm.n+1),_xlpm.prz,IF(Kalkulator!$I$15:$I$19="",Kalkulator!$D$15:$D$19,Kalkulator!$I$15:$I$19),_xlpm.wyj,IF(Kalkulator!$J$15:$J$19="",IF(Kalkulator!$C$16:$C$20<>"",Kalkulator!$D$16:$D$20,Kalkulator!$D$20),Kalkulator!$J$15:$J$19),_xlpm.v,IF(_xlpm.puste,0,N(IF(_xlpm.i<=_xlpm.n,INDEX(_xlpm.prz,_xlpm.i),_xlpm.kon))),IF(_xlpm.v=0,"",MOD(_xlpm.v,1)))} | H49: {=_xlfn.LET(_xlpm.n,COUNTIF(Kalkulator!$C$15:$C$19,"?*"),_xlpm.i,5,_xlpm.p,IF(Kalkulator!$H$15:$H$19<>"",Kalkulator!$H$15:$H$19,Kalkulator!$C$15:$C$19),_xlpm.dom,IF(Kalkulator!$C$10="","Polska",Kalkulator!$C$10),_xlpm.pocz,IF(Kalkulator!$K$5="",Kalkulator!$D$15,Kalkulator!$K$5),_xlpm.kon,IF(Kalkulator!$K$6="",Kalkulator!$D$20,Kalkulator!$K$6),_xlpm.puste,OR(_xlpm.n=0,_xlpm.i>_xlpm.n+1),_xlpm.prz,IF(Kalkulator!$I$15:$I$19="",Kalkulator!$D$15:$D$19,Kalkulator!$I$15:$I$19),_xlpm.wyj,IF(Kalkulator!$J$15:$J$19="",IF(Kalkulator!$C$16:$C$20<>"",Kalkulator!$D$16:$D$20,Kalkulator!$D$20),Kalkulator!$J$15:$J$19),_xlpm.s,IF(_xlpm.puste,"",INDEX(Kalkulator!$K$15:$K$20,IF(_xlpm.i<=_xlpm.n,_xlpm.i,6))&""),IF(_xlpm.puste,"",IF(_xlpm.s="",Kalkulator!$C$11&"",_xlpm.s)))} | I49: {=_xlfn.LET(_xlpm.n,COUNTIF(Kalkulator!$C$15:$C$19,"?*"),_xlpm.i,5,_xlpm.p,IF(Kalkulator!$H$15:$H$19<>"",Kalkulator!$H$15:$H$19,Kalkulator!$C$15:$C$19),_xlpm.dom,IF(Kalkulator!$C$10="","Polska",Kalkulator!$C$10),_xlpm.pocz,IF(Kalkulator!$K$5="",Kalkulator!$D$15,Kalkulator!$K$5),_xlpm.kon,IF(Kalkulator!$K$6="",Kalkulator!$D$20,Kalkulator!$K$6),_xlpm.puste,OR(_xlpm.n=0,_xlpm.i>_xlpm.n+1),_xlpm.prz,IF(Kalkulator!$I$15:$I$19="",Kalkulator!$D$15:$D$19,Kalkulator!$I$15:$I$19),_xlpm.wyj,IF(Kalkulator!$J$15:$J$19="",IF(Kalkulator!$C$16:$C$20<>"",Kalkulator!$D$16:$D$20,Kalkulator!$D$20),Kalkulator!$J$15:$J$19),IF(_xlpm.puste,"",INDEX(Kalkulator!$N$15:$N$20,IF(_xlpm.i<=_xlpm.n,_xlpm.i,6))))}
B50: {=_xlfn.LET(_xlpm.n,COUNTIF(Kalkulator!$C$15:$C$19,"?*"),_xlpm.i,6,_xlpm.p,IF(Kalkulator!$H$15:$H$19<>"",Kalkulator!$H$15:$H$19,Kalkulator!$C$15:$C$19),_xlpm.dom,IF(Kalkulator!$C$10="","Polska",Kalkulator!$C$10),_xlpm.pocz,IF(Kalkulator!$K$5="",Kalkulator!$D$15,Kalkulator!$K$5),_xlpm.kon,IF(Kalkulator!$K$6="",Kalkulator!$D$20,Kalkulator!$K$6),_xlpm.puste,OR(_xlpm.n=0,_xlpm.i>_xlpm.n+1),_xlpm.prz,IF(Kalkulator!$I$15:$I$19="",Kalkulator!$D$15:$D$19,Kalkulator!$I$15:$I$19),_xlpm.wyj,IF(Kalkulator!$J$15:$J$19="",IF(Kalkulator!$C$16:$C$20<>"",Kalkulator!$D$16:$D$20,Kalkulator!$D$20),Kalkulator!$J$15:$J$19),IF(_xlpm.puste,"",IF(_xlpm.i=1,_xlpm.dom,INDEX(_xlpm.p,_xlpm.i-1))))} | C50: {=_xlfn.LET(_xlpm.n,COUNTIF(Kalkulator!$C$15:$C$19,"?*"),_xlpm.i,6,_xlpm.p,IF(Kalkulator!$H$15:$H$19<>"",Kalkulator!$H$15:$H$19,Kalkulator!$C$15:$C$19),_xlpm.dom,IF(Kalkulator!$C$10="","Polska",Kalkulator!$C$10),_xlpm.pocz,IF(Kalkulator!$K$5="",Kalkulator!$D$15,Kalkulator!$K$5),_xlpm.kon,IF(Kalkulator!$K$6="",Kalkulator!$D$20,Kalkulator!$K$6),_xlpm.puste,OR(_xlpm.n=0,_xlpm.i>_xlpm.n+1),_xlpm.prz,IF(Kalkulator!$I$15:$I$19="",Kalkulator!$D$15:$D$19,Kalkulator!$I$15:$I$19),_xlpm.wyj,IF(Kalkulator!$J$15:$J$19="",IF(Kalkulator!$C$16:$C$20<>"",Kalkulator!$D$16:$D$20,Kalkulator!$D$20),Kalkulator!$J$15:$J$19),_xlpm.v,IF(_xlpm.puste,0,N(IF(_xlpm.i=1,_xlpm.pocz,INDEX(_xlpm.wyj,_xlpm.i-1)))),IF(_xlpm.v=0,"",INT(_xlpm.v)))} | D50: {=_xlfn.LET(_xlpm.n,COUNTIF(Kalkulator!$C$15:$C$19,"?*"),_xlpm.i,6,_xlpm.p,IF(Kalkulator!$H$15:$H$19<>"",Kalkulator!$H$15:$H$19,Kalkulator!$C$15:$C$19),_xlpm.dom,IF(Kalkulator!$C$10="","Polska",Kalkulator!$C$10),_xlpm.pocz,IF(Kalkulator!$K$5="",Kalkulator!$D$15,Kalkulator!$K$5),_xlpm.kon,IF(Kalkulator!$K$6="",Kalkulator!$D$20,Kalkulator!$K$6),_xlpm.puste,OR(_xlpm.n=0,_xlpm.i>_xlpm.n+1),_xlpm.prz,IF(Kalkulator!$I$15:$I$19="",Kalkulator!$D$15:$D$19,Kalkulator!$I$15:$I$19),_xlpm.wyj,IF(Kalkulator!$J$15:$J$19="",IF(Kalkulator!$C$16:$C$20<>"",Kalkulator!$D$16:$D$20,Kalkulator!$D$20),Kalkulator!$J$15:$J$19),_xlpm.v,IF(_xlpm.puste,0,N(IF(_xlpm.i=1,_xlpm.pocz,INDEX(_xlpm.wyj,_xlpm.i-1)))),IF(_xlpm.v=0,"",MOD(_xlpm.v,1)))} | E50: {=_xlfn.LET(_xlpm.n,COUNTIF(Kalkulator!$C$15:$C$19,"?*"),_xlpm.i,6,_xlpm.p,IF(Kalkulator!$H$15:$H$19<>"",Kalkulator!$H$15:$H$19,Kalkulator!$C$15:$C$19),_xlpm.dom,IF(Kalkulator!$C$10="","Polska",Kalkulator!$C$10),_xlpm.pocz,IF(Kalkulator!$K$5="",Kalkulator!$D$15,Kalkulator!$K$5),_xlpm.kon,IF(Kalkulator!$K$6="",Kalkulator!$D$20,Kalkulator!$K$6),_xlpm.puste,OR(_xlpm.n=0,_xlpm.i>_xlpm.n+1),_xlpm.prz,IF(Kalkulator!$I$15:$I$19="",Kalkulator!$D$15:$D$19,Kalkulator!$I$15:$I$19),_xlpm.wyj,IF(Kalkulator!$J$15:$J$19="",IF(Kalkulator!$C$16:$C$20<>"",Kalkulator!$D$16:$D$20,Kalkulator!$D$20),Kalkulator!$J$15:$J$19),IF(_xlpm.puste,"",IF(_xlpm.i<=_xlpm.n,INDEX(_xlpm.p,_xlpm.i),_xlpm.dom)))} | F50: {=_xlfn.LET(_xlpm.n,COUNTIF(Kalkulator!$C$15:$C$19,"?*"),_xlpm.i,6,_xlpm.p,IF(Kalkulator!$H$15:$H$19<>"",Kalkulator!$H$15:$H$19,Kalkulator!$C$15:$C$19),_xlpm.dom,IF(Kalkulator!$C$10="","Polska",Kalkulator!$C$10),_xlpm.pocz,IF(Kalkulator!$K$5="",Kalkulator!$D$15,Kalkulator!$K$5),_xlpm.kon,IF(Kalkulator!$K$6="",Kalkulator!$D$20,Kalkulator!$K$6),_xlpm.puste,OR(_xlpm.n=0,_xlpm.i>_xlpm.n+1),_xlpm.prz,IF(Kalkulator!$I$15:$I$19="",Kalkulator!$D$15:$D$19,Kalkulator!$I$15:$I$19),_xlpm.wyj,IF(Kalkulator!$J$15:$J$19="",IF(Kalkulator!$C$16:$C$20<>"",Kalkulator!$D$16:$D$20,Kalkulator!$D$20),Kalkulator!$J$15:$J$19),_xlpm.v,IF(_xlpm.puste,0,N(IF(_xlpm.i<=_xlpm.n,INDEX(_xlpm.prz,_xlpm.i),_xlpm.kon))),IF(_xlpm.v=0,"",INT(_xlpm.v)))} | G50: {=_xlfn.LET(_xlpm.n,COUNTIF(Kalkulator!$C$15:$C$19,"?*"),_xlpm.i,6,_xlpm.p,IF(Kalkulator!$H$15:$H$19<>"",Kalkulator!$H$15:$H$19,Kalkulator!$C$15:$C$19),_xlpm.dom,IF(Kalkulator!$C$10="","Polska",Kalkulator!$C$10),_xlpm.pocz,IF(Kalkulator!$K$5="",Kalkulator!$D$15,Kalkulator!$K$5),_xlpm.kon,IF(Kalkulator!$K$6="",Kalkulator!$D$20,Kalkulator!$K$6),_xlpm.puste,OR(_xlpm.n=0,_xlpm.i>_xlpm.n+1),_xlpm.prz,IF(Kalkulator!$I$15:$I$19="",Kalkulator!$D$15:$D$19,Kalkulator!$I$15:$I$19),_xlpm.wyj,IF(Kalkulator!$J$15:$J$19="",IF(Kalkulator!$C$16:$C$20<>"",Kalkulator!$D$16:$D$20,Kalkulator!$D$20),Kalkulator!$J$15:$J$19),_xlpm.v,IF(_xlpm.puste,0,N(IF(_xlpm.i<=_xlpm.n,INDEX(_xlpm.prz,_xlpm.i),_xlpm.kon))),IF(_xlpm.v=0,"",MOD(_xlpm.v,1)))} | H50: {=_xlfn.LET(_xlpm.n,COUNTIF(Kalkulator!$C$15:$C$19,"?*"),_xlpm.i,6,_xlpm.p,IF(Kalkulator!$H$15:$H$19<>"",Kalkulator!$H$15:$H$19,Kalkulator!$C$15:$C$19),_xlpm.dom,IF(Kalkulator!$C$10="","Polska",Kalkulator!$C$10),_xlpm.pocz,IF(Kalkulator!$K$5="",Kalkulator!$D$15,Kalkulator!$K$5),_xlpm.kon,IF(Kalkulator!$K$6="",Kalkulator!$D$20,Kalkulator!$K$6),_xlpm.puste,OR(_xlpm.n=0,_xlpm.i>_xlpm.n+1),_xlpm.prz,IF(Kalkulator!$I$15:$I$19="",Kalkulator!$D$15:$D$19,Kalkulator!$I$15:$I$19),_xlpm.wyj,IF(Kalkulator!$J$15:$J$19="",IF(Kalkulator!$C$16:$C$20<>"",Kalkulator!$D$16:$D$20,Kalkulator!$D$20),Kalkulator!$J$15:$J$19),_xlpm.s,IF(_xlpm.puste,"",INDEX(Kalkulator!$K$15:$K$20,IF(_xlpm.i<=_xlpm.n,_xlpm.i,6))&""),IF(_xlpm.puste,"",IF(_xlpm.s="",Kalkulator!$C$11&"",_xlpm.s)))} | I50: {=_xlfn.LET(_xlpm.n,COUNTIF(Kalkulator!$C$15:$C$19,"?*"),_xlpm.i,6,_xlpm.p,IF(Kalkulator!$H$15:$H$19<>"",Kalkulator!$H$15:$H$19,Kalkulator!$C$15:$C$19),_xlpm.dom,IF(Kalkulator!$C$10="","Polska",Kalkulator!$C$10),_xlpm.pocz,IF(Kalkulator!$K$5="",Kalkulator!$D$15,Kalkulator!$K$5),_xlpm.kon,IF(Kalkulator!$K$6="",Kalkulator!$D$20,Kalkulator!$K$6),_xlpm.puste,OR(_xlpm.n=0,_xlpm.i>_xlpm.n+1),_xlpm.prz,IF(Kalkulator!$I$15:$I$19="",Kalkulator!$D$15:$D$19,Kalkulator!$I$15:$I$19),_xlpm.wyj,IF(Kalkulator!$J$15:$J$19="",IF(Kalkulator!$C$16:$C$20<>"",Kalkulator!$D$16:$D$20,Kalkulator!$D$20),Kalkulator!$J$15:$J$19),IF(_xlpm.puste,"",INDEX(Kalkulator!$N$15:$N$20,IF(_xlpm.i<=_xlpm.n,_xlpm.i,6))))}
